Workbook

Sheet RAW
A4: From Formulas: Soul Energy K3 Cell
A5: Accumulative Total Cost
A6: 400
A7: 1200
A8: 2800
A9: 6000
A10: 12400
A11: 25200
A12: 50800
A13: 102000
A14: 204400
A15: 409200
A16: 818800
A17: 1638000
... A22: 52428400

Sheet Adventurers
C1: CHAR CALC | G1: FAUNA (HERBIVORES) AVERAGE
A2: Below Child years is equals to shares of parents soul being infused | C2: Child | D2: =D3/12 -> 0.018939394 | F2: Child | G2: =G3/12 -> 1.9886364 | H2: =H3/12 -> 1.7992424 | I2: =I3/12 -> 1.6098485 | J2: =J3/12 -> 4.1666667 | K2: =K3/12 -> 1.3257576 | L2: =L3/12 -> 2.4621212 | M2: =M3/12 -> 1.5909091 | N2: =N3/12 -> 1.4015152 | ... AB2: =AB3/12 -> 0.018939394
C3: Adulthood | D3: =D4/4.4 -> 0.22727273 | F3: Adulthood | G3: =G4/4.4 -> 23.863636 | H3: =H4/4.4 -> 21.590909 | I3: =I4/4.4 -> 19.318182 | J3: =J4/4.4 -> 50 | K3: =K4/4.4 -> 15.909091 | L3: =L4/4.4 -> 29.545455 | M3: =M4/4.4 -> 19.090909 | N3: =N4/4.4 -> 16.818182 | ... AB3: =AB4/4.4 -> 0.22727273
C4: Lifespan | D4: 1 | F4: Lifespan | G4: 105 | H4: 95 | I4: 85 | J4: 220 | K4: 70 | L4: 130 | M4: 84 | N4: 74 | O4: 1 | P4: 1 | Q4: 1 | R4: 1 | S4: 1 | T4: 1 | U4: 1 | V4: 1 | W4: 1 | X4: 1 | Y4: 1 | Z4: 1 | AA4: 1 | AB4: 1
C5: Soul Recharge/Day | D5: 1 | F5: Soul Recharge/Day | G5: 139 | H5: 17 | I5: 20 | J5: 9 | K5: 7 | L5: 5 | M5: 15 | N5: 11 | O5: 1 | P5: 1 | Q5: 1 | R5: 1 | S5: 1 | T5: 1 | U5: 1 | V5: 1 | W5: 1 | X5: 1 | Y5: 1 | Z5: 1 | AA5: 1 | AB5: 1
G6: Average Total Years to Reach Tier
A7: Accumulative Total Cost | C7: Soul Energy Tier | D7: Char | F7: Soul Energy Tier | G7: Harry | H7: Magi | I7: Fernan | J7: Hiromi | K7: Morika | L7: Takeo | M7: July | N7: Kaiana
A8: =RAW!$A$6 -> 400 | C8: Tier I | D8: =($A8/D$5)/365 -> 1.0958904 | F8: Tier I | G8: =($A8/G$5)/365 -> 0.0078841037 | H8: =($A8/H$5)/365 -> 0.064464142 | I8: =($A8/I$5)/365 -> 0.054794521 | J8: =($A8/J$5)/365 -> 0.1217656 | K8: =($A8/K$5)/365 -> 0.15655577 | L8: =($A8/L$5)/365 -> 0.21917808 | M8: =($A8/M$5)/365 -> 0.073059361 | N8: =($A8/N$5)/365 -> 0.099626401 | ... AB8: =($A8/AB$5)/365 -> 1.0958904
A9: =RAW!$A$7 -> 1200 | C9: Tier II | D9: =($A9/D$5)/365 -> 3.2876712 | F9: Tier II | G9: =($A9/G$5)/365 -> 0.023652311 | H9: =($A9/H$5)/365 -> 0.19339243 | I9: =($A9/I$5)/365 -> 0.16438356 | J9: =($A9/J$5)/365 -> 0.3652968 | K9: =($A9/K$5)/365 -> 0.46966732 | L9: =($A9/L$5)/365 -> 0.65753425 | M9: =($A9/M$5)/365 -> 0.21917808 | N9: =($A9/N$5)/365 -> 0.2988792 | ... AB9: =($A9/AB$5)/365 -> 3.2876712
A10: =RAW!$A$8 -> 2800 | C10: Tier III | D10: =($A10/D$5)/365 -> 7.6712329 | F10: Tier III | G10: =($A10/G$5)/365 -> 0.055188726 | H10: =($A10/H$5)/365 -> 0.45124899 | I10: =($A10/I$5)/365 -> 0.38356164 | J10: =($A10/J$5)/365 -> 0.85235921 | K10: =($A10/K$5)/365 -> 1.0958904 | L10: =($A10/L$5)/365 -> 1.5342466 | M10: =($A10/M$5)/365 -> 0.51141553 | N10: =($A10/N$5)/365 -> 0.69738481 | ... AB10: =($A10/AB$5)/365 -> 7.6712329
A11: =RAW!$A$9 -> 6000 | C11: Tier IV | D11: =($A11/D$5)/365 -> 16.438356 | F11: Tier IV | G11: =($A11/G$5)/365 -> 0.11826156 | H11: =($A11/H$5)/365 -> 0.96696213 | I11: =($A11/I$5)/365 -> 0.82191781 | J11: =($A11/J$5)/365 -> 1.826484 | K11: =($A11/K$5)/365 -> 2.3483366 | L11: =($A11/L$5)/365 -> 3.2876712 | M11: =($A11/M$5)/365 -> 1.0958904 | N11: =($A11/N$5)/365 -> 1.494396 | ... AB11: =($A11/AB$5)/365 -> 16.438356
A12: =RAW!$A$10 -> 12400 | C12: Tier V | D12: =($A12/D$5)/365 -> 33.972603 | F12: Tier V | G12: =($A12/G$5)/365 -> 0.24440721 | H12: =($A12/H$5)/365 -> 1.9983884 | I12: =($A12/I$5)/365 -> 1.6986301 | J12: =($A12/J$5)/365 -> 3.7747336 | K12: =($A12/K$5)/365 -> 4.853229 | L12: =($A12/L$5)/365 -> 6.7945205 | M12: =($A12/M$5)/365 -> 2.2648402 | N12: =($A12/N$5)/365 -> 3.0884184 | ... AB12: =($A12/AB$5)/365 -> 33.972603
A13: =RAW!$A$11 -> 25200 | C13: Tier VI | D13: =($A13/D$5)/365 -> 69.041096 | F13: Tier VI | G13: =($A13/G$5)/365 -> 0.49669853 | H13: =($A13/H$5)/365 -> 4.0612409 | I13: =($A13/I$5)/365 -> 3.4520548 | J13: =($A13/J$5)/365 -> 7.6712329 | K13: =($A13/K$5)/365 -> 9.8630137 | L13: =($A13/L$5)/365 -> 13.808219 | M13: =($A13/M$5)/365 -> 4.6027397 | N13: =($A13/N$5)/365 -> 6.2764633 | ... AB13: =($A13/AB$5)/365 -> 69.041096
A14: =RAW!$A$12 -> 50800 | C14: Tier VII | D14: =($A14/D$5)/365 -> 139.17808 | F14: Tier VII | G14: =($A14/G$5)/365 -> 1.0012812 | H14: =($A14/H$5)/365 -> 8.186946 | I14: =($A14/I$5)/365 -> 6.9589041 | J14: =($A14/J$5)/365 -> 15.464231 | K14: =($A14/K$5)/365 -> 19.882583 | L14: =($A14/L$5)/365 -> 27.835616 | M14: =($A14/M$5)/365 -> 9.2785388 | N14: =($A14/N$5)/365 -> 12.652553 | ... AB14: =($A14/AB$5)/365 -> 139.17808
A15: =RAW!$A$13 -> 102000 | C15: Tier VIII | D15: =($A15/D$5)/365 -> 279.45205 | F15: Tier VIII | G15: =($A15/G$5)/365 -> 2.0104464 | H15: =($A15/H$5)/365 -> 16.438356 | I15: =($A15/I$5)/365 -> 13.972603 | J15: =($A15/J$5)/365 -> 31.050228 | K15: =($A15/K$5)/365 -> 39.921722 | L15: =($A15/L$5)/365 -> 55.890411 | M15: =($A15/M$5)/365 -> 18.630137 | N15: =($A15/N$5)/365 -> 25.404732 | ... AB15: =($A15/AB$5)/365 -> 279.45205
A16: =RAW!$A$14 -> 204400 | C16: Tier IX | D16: =($A16/D$5)/365 -> 560 | F16: Tier IX | G16: =($A16/G$5)/365 -> 4.028777 | H16: =($A16/H$5)/365 -> 32.941176 | I16: =($A16/I$5)/365 -> 28 | J16: =($A16/J$5)/365 -> 62.222222 | K16: =($A16/K$5)/365 -> 80 | L16: =($A16/L$5)/365 -> 112 | M16: =($A16/M$5)/365 -> 37.333333 | N16: =($A16/N$5)/365 -> 50.909091 | ... AB16: =($A16/AB$5)/365 -> 560
A17: =RAW!$A$15 -> 409200 | C17: Tier X | D17: =($A17/D$5)/365 -> 1121.0959 | F17: Tier X | G17: =($A17/G$5)/365 -> 8.0654381 | H17: =($A17/H$5)/365 -> 65.946817 | I17: =($A17/I$5)/365 -> 56.054795 | J17: =($A17/J$5)/365 -> 124.56621 | K17: =($A17/K$5)/365 -> 160.15656 | L17: =($A17/L$5)/365 -> 224.21918 | M17: =($A17/M$5)/365 -> 74.739726 | N17: =($A17/N$5)/365 -> 101.91781 | ... AB17: =($A17/AB$5)/365 -> 1121.0959
A18: =RAW!$A$16 -> 818800 | C18: Tier XI | D18: =($A18/D$5)/365 -> 2243.2877 | F18: Tier XI | G18: =($A18/G$5)/365 -> 16.13876 | H18: =($A18/H$5)/365 -> 131.9581 | I18: =($A18/I$5)/365 -> 112.16438 | J18: =($A18/J$5)/365 -> 249.25419 | K18: =($A18/K$5)/365 -> 320.46967 | L18: =($A18/L$5)/365 -> 448.65753 | M18: =($A18/M$5)/365 -> 149.55251 | N18: =($A18/N$5)/365 -> 203.93524 | ... AB18: =($A18/AB$5)/365 -> 2243.2877
A19: =RAW!$A$17 -> 1638000 | C19: Tier XII | D19: =($A19/D$5)/365 -> 4487.6712 | F19: Tier XII | G19: =($A19/G$5)/365 -> 32.285405 | H19: =($A19/H$5)/365 -> 263.98066 | I19: =($A19/I$5)/365 -> 224.38356 | J19: =($A19/J$5)/365 -> 498.63014 | K19: =($A19/K$5)/365 -> 641.09589 | L19: =($A19/L$5)/365 -> 897.53425 | M19: =($A19/M$5)/365 -> 299.17808 | N19: =($A19/N$5)/365 -> 407.97011 | ... AB19: =($A19/AB$5)/365 -> 4487.6712
A20: =RAW!$A$18 -> 3276400 | C20: Tier XIII | D20: =($A20/D$5)/365 -> 8976.4384 | F20: Tier XIII | G20: =($A20/G$5)/365 -> 64.578693 | H20: =($A20/H$5)/365 -> 528.02579 | I20: =($A20/I$5)/365 -> 448.82192 | J20: =($A20/J$5)/365 -> 997.38204 | K20: =($A20/K$5)/365 -> 1282.3483 | L20: =($A20/L$5)/365 -> 1795.2877 | M20: =($A20/M$5)/365 -> 598.42922 | N20: =($A20/N$5)/365 -> 816.03985 | ... AB20: =($A20/AB$5)/365 -> 8976.4384
A21: =RAW!$A$19 -> 6553200 | C21: Tier XIV | D21: =($A21/D$5)/365 -> 17953.973 | F21: Tier XIV | G21: =($A21/G$5)/365 -> 129.16527 | H21: =($A21/H$5)/365 -> 1056.116 | I21: =($A21/I$5)/365 -> 897.69863 | J21: =($A21/J$5)/365 -> 1994.8858 | K21: =($A21/K$5)/365 -> 2564.8532 | L21: =($A21/L$5)/365 -> 3590.7945 | M21: =($A21/M$5)/365 -> 1196.9315 | N21: =($A21/N$5)/365 -> 1632.1793 | ... AB21: =($A21/AB$5)/365 -> 17953.973
A22: =RAW!$A$20 -> 13106800 | C22: Tier XV | D22: =($A22/D$5)/365 -> 35909.041 | F22: Tier XV | G22: =($A22/G$5)/365 -> 258.33843 | H22: =($A22/H$5)/365 -> 2112.2965 | I22: =($A22/I$5)/365 -> 1795.4521 | J22: =($A22/J$5)/365 -> 3989.8935 | K22: =($A22/K$5)/365 -> 5129.863 | L22: =($A22/L$5)/365 -> 7181.8082 | M22: =($A22/M$5)/365 -> 2393.9361 | N22: =($A22/N$5)/365 -> 3264.4583 | ... AB22: =($A22/AB$5)/365 -> 35909.041
A23: =RAW!$A$21 -> 26214000 | C23: Tier XVI | D23: =($A23/D$5)/365 -> 71819.178 | F23: Tier XVI | G23: =($A23/G$5)/365 -> 516.68473 | H23: =($A23/H$5)/365 -> 4224.6575 | I23: =($A23/I$5)/365 -> 3590.9589 | J23: =($A23/J$5)/365 -> 7979.9087 | K23: =($A23/K$5)/365 -> 10259.883 | L23: =($A23/L$5)/365 -> 14363.836 | M23: =($A23/M$5)/365 -> 4787.9452 | N23: =($A23/N$5)/365 -> 6529.0162 | ... AB23: =($A23/AB$5)/365 -> 71819.178
A24: =RAW!$A$22 -> 52428400 | C24: Tier XVII | D24: =($A24/D$5)/365 -> 143639.45 | F24: Tier XVII | G24: =($A24/G$5)/365 -> 1033.3774 | H24: =($A24/H$5)/365 -> 8449.3795 | I24: =($A24/I$5)/365 -> 7181.9726 | J24: =($A24/J$5)/365 -> 15959.939 | K24: =($A24/K$5)/365 -> 20519.922 | L24: =($A24/L$5)/365 -> 28727.89 | M24: =($A24/M$5)/365 -> 9575.9635 | N24: =($A24/N$5)/365 -> 13058.132 | ... AB24: =($A24/AB$5)/365 -> 143639.45
G25: How Many days does it take to recharge a spell
A26: Spell Soul Cost | C26: Soul Energy Tier | D26: Char | F26: Soul Energy Tier | G26: =G7 -> Harry | H26: =H7 -> Magi | I26: =I7 -> Fernan | J26: =J7 -> Hiromi | K26: =K7 -> Morika | L26: =L7 -> Takeo | M26: =M7 -> July | N26: =N7 -> Kaiana | ... AB26: =AB7 -> 0
A27: =RAW!$A$6 -> 400 | C27: Tier I | D27: =$A27/D$5 -> 400 | F27: Tier I | G27: =$A27/G$5 -> 2.8776978 | H27: =$A27/H$5 -> 23.529412 | I27: =$A27/I$5 -> 20 | J27: =$A27/J$5 -> 44.444444 | K27: =$A27/K$5 -> 57.142857 | L27: =$A27/L$5 -> 80 | M27: =$A27/M$5 -> 26.666667 | N27: =$A27/N$5 -> 36.363636 | ... AB27: =$A27/AB$5 -> 400
A28: =RAW!$A$7 -> 1200 | C28: Tier II | D28: =$A28/D$5 -> 1200 | F28: Tier II | G28: =$A28/G$5 -> 8.6330935 | H28: =$A28/H$5 -> 70.588235 | I28: =$A28/I$5 -> 60 | J28: =$A28/J$5 -> 133.33333 | K28: =$A28/K$5 -> 171.42857 | L28: =$A28/L$5 -> 240 | M28: =$A28/M$5 -> 80 | N28: =$A28/N$5 -> 109.09091 | ... AB28: =$A28/AB$5 -> 1200
A29: =RAW!$A$8 -> 2800 | C29: Tier III | D29: =$A29/D$5 -> 2800 | F29: Tier III | G29: =$A29/G$5 -> 20.143885 | H29: =$A29/H$5 -> 164.70588 | I29: =$A29/I$5 -> 140 | J29: =$A29/J$5 -> 311.11111 | K29: =$A29/K$5 -> 400 | L29: =$A29/L$5 -> 560 | M29: =$A29/M$5 -> 186.66667 | N29: =$A29/N$5 -> 254.54545 | ... AB29: =$A29/AB$5 -> 2800
A30: =RAW!$A$9 -> 6000 | C30: Tier IV | D30: =$A30/D$5 -> 6000 | F30: Tier IV | G30: =$A30/G$5 -> 43.165468 | H30: =$A30/H$5 -> 352.94118 | I30: =$A30/I$5 -> 300 | J30: =$A30/J$5 -> 666.66667 | K30: =$A30/K$5 -> 857.14286 | L30: =$A30/L$5 -> 1200 | M30: =$A30/M$5 -> 400 | N30: =$A30/N$5 -> 545.45455 | ... AB30: =$A30/AB$5 -> 6000
A31: =RAW!$A$10 -> 12400 | C31: Tier V | D31: =$A31/D$5 -> 12400 | F31: Tier V | G31: =$A31/G$5 -> 89.208633 | H31: =$A31/H$5 -> 729.41176 | I31: =$A31/I$5 -> 620 | J31: =$A31/J$5 -> 1377.7778 | K31: =$A31/K$5 -> 1771.4286 | L31: =$A31/L$5 -> 2480 | M31: =$A31/M$5 -> 826.66667 | N31: =$A31/N$5 -> 1127.2727 | ... AB31: =$A31/AB$5 -> 12400
A32: =RAW!$A$11 -> 25200 | C32: Tier VI | D32: =$A32/D$5 -> 25200 | F32: Tier VI | G32: =$A32/G$5 -> 181.29496 | H32: =$A32/H$5 -> 1482.3529 | I32: =$A32/I$5 -> 1260 | J32: =$A32/J$5 -> 2800 | K32: =$A32/K$5 -> 3600 | L32: =$A32/L$5 -> 5040 | M32: =$A32/M$5 -> 1680 | N32: =$A32/N$5 -> 2290.9091 | ... AB32: =$A32/AB$5 -> 25200
A33: =RAW!$A$12 -> 50800 | C33: Tier VII | D33: =$A33/D$5 -> 50800 | F33: Tier VII | G33: =$A33/G$5 -> 365.46763 | H33: =$A33/H$5 -> 2988.2353 | I33: =$A33/I$5 -> 2540 | J33: =$A33/J$5 -> 5644.4444 | K33: =$A33/K$5 -> 7257.1429 | L33: =$A33/L$5 -> 10160 | M33: =$A33/M$5 -> 3386.6667 | N33: =$A33/N$5 -> 4618.1818 | ... AB33: =$A33/AB$5 -> 50800
A34: =RAW!$A$13 -> 102000 | C34: Tier VIII | D34: =$A34/D$5 -> 102000 | F34: Tier VIII | G34: =$A34/G$5 -> 733.81295 | H34: =$A34/H$5 -> 6000 | I34: =$A34/I$5 -> 5100 | J34: =$A34/J$5 -> 11333.333 | K34: =$A34/K$5 -> 14571.429 | L34: =$A34/L$5 -> 20400 | M34: =$A34/M$5 -> 6800 | N34: =$A34/N$5 -> 9272.7273 | ... AB34: =$A34/AB$5 -> 102000
A35: =RAW!$A$14 -> 204400 | C35: Tier IX | D35: =$A35/D$5 -> 204400 | F35: Tier IX | G35: =$A35/G$5 -> 1470.5036 | H35: =$A35/H$5 -> 12023.529 | I35: =$A35/I$5 -> 10220 | J35: =$A35/J$5 -> 22711.111 | K35: =$A35/K$5 -> 29200 | L35: =$A35/L$5 -> 40880 | M35: =$A35/M$5 -> 13626.667 | N35: =$A35/N$5 -> 18581.818 | ... AB35: =$A35/AB$5 -> 204400
A36: =RAW!$A$15 -> 409200 | C36: Tier X | D36: =$A36/D$5 -> 409200 | F36: Tier X | G36: =$A36/G$5 -> 2943.8849 | H36: =$A36/H$5 -> 24070.588 | I36: =$A36/I$5 -> 20460 | J36: =$A36/J$5 -> 45466.667 | K36: =$A36/K$5 -> 58457.143 | L36: =$A36/L$5 -> 81840 | M36: =$A36/M$5 -> 27280 | N36: =$A36/N$5 -> 37200 | ... AB36: =$A36/AB$5 -> 409200
A37: =RAW!$A$16 -> 818800 | C37: Tier XI | D37: =$A37/D$5 -> 818800 | F37: Tier XI | G37: =$A37/G$5 -> 5890.6475 | H37: =$A37/H$5 -> 48164.706 | I37: =$A37/I$5 -> 40940 | J37: =$A37/J$5 -> 90977.778 | K37: =$A37/K$5 -> 116971.43 | L37: =$A37/L$5 -> 163760 | M37: =$A37/M$5 -> 54586.667 | N37: =$A37/N$5 -> 74436.364 | ... AB37: =$A37/AB$5 -> 818800
A38: =RAW!$A$17 -> 1638000 | C38: Tier XII | D38: =$A38/D$5 -> 1638000 | F38: Tier XII | G38: =$A38/G$5 -> 11784.173 | H38: =$A38/H$5 -> 96352.941 | I38: =$A38/I$5 -> 81900 | J38: =$A38/J$5 -> 182000 | K38: =$A38/K$5 -> 234000 | L38: =$A38/L$5 -> 327600 | M38: =$A38/M$5 -> 109200 | N38: =$A38/N$5 -> 148909.09 | ... AB38: =$A38/AB$5 -> 1638000
A39: =RAW!$A$18 -> 3276400 | C39: Tier XIII | D39: =$A39/D$5 -> 3276400 | F39: Tier XIII | G39: =$A39/G$5 -> 23571.223 | H39: =$A39/H$5 -> 192729.41 | I39: =$A39/I$5 -> 163820 | J39: =$A39/J$5 -> 364044.44 | K39: =$A39/K$5 -> 468057.14 | L39: =$A39/L$5 -> 655280 | M39: =$A39/M$5 -> 218426.67 | N39: =$A39/N$5 -> 297854.55 | ... AB39: =$A39/AB$5 -> 3276400
A40: =RAW!$A$19 -> 6553200 | C40: Tier XIV | D40: =$A40/D$5 -> 6553200 | F40: Tier XIV | G40: =$A40/G$5 -> 47145.324 | H40: =$A40/H$5 -> 385482.35 | I40: =$A40/I$5 -> 327660 | J40: =$A40/J$5 -> 728133.33 | K40: =$A40/K$5 -> 936171.43 | L40: =$A40/L$5 -> 1310640 | M40: =$A40/M$5 -> 436880 | N40: =$A40/N$5 -> 595745.45 | ... AB40: =$A40/AB$5 -> 6553200
...

Sheet Blood
C1: CHAR CALC | G1: FAUNA (HERBIVORES) AVERAGE
A2: Below Child years is equals to shares of parents soul being infused | C2: Child | D2: =D3/12 -> 0.018939394 | F2: Child | G2: =G3/12 -> 2.4621212 | H2: =H3/12 -> 2.0833333 | I2: =I3/12 -> 0.018939394 | J2: =J3/12 -> 0.018939394 | K2: =K3/12 -> 0.018939394 | L2: =L3/12 -> 0.018939394 | M2: =M3/12 -> 0.018939394 | N2: =N3/12 -> 0.018939394 | ... AB2: =AB3/12 -> 0.018939394
C3: Adulthood | D3: =D4/4.4 -> 0.22727273 | F3: Adulthood | G3: =G4/4.4 -> 29.545455 | H3: =H4/4.4 -> 25 | I3: =I4/4.4 -> 0.22727273 | J3: =J4/4.4 -> 0.22727273 | K3: =K4/4.4 -> 0.22727273 | L3: =L4/4.4 -> 0.22727273 | M3: =M4/4.4 -> 0.22727273 | N3: =N4/4.4 -> 0.22727273 | ... AB3: =AB4/4.4 -> 0.22727273
C4: Lifespan | D4: 1 | F4: Lifespan | G4: 130 | H4: 110 | I4: 1 | J4: 1 | K4: 1 | L4: 1 | M4: 1 | N4: 1 | O4: 1 | P4: 1 | Q4: 1 | R4: 1 | S4: 1 | T4: 1 | U4: 1 | V4: 1 | W4: 1 | X4: 1 | Y4: 1 | Z4: 1 | AA4: 1 | AB4: 1
C5: Soul Recharge/Day | D5: 1 | F5: Soul Recharge/Day | G5: 10 | H5: 12 | I5: 1 | J5: 1 | K5: 1 | L5: 1 | M5: 1 | N5: 1 | O5: 1 | P5: 1 | Q5: 1 | R5: 1 | S5: 1 | T5: 1 | U5: 1 | V5: 1 | W5: 1 | X5: 1 | Y5: 1 | Z5: 1 | AA5: 1 | AB5: 1
G6: Average Total Years to Reach Tier
A7: Accumulative Total Cost | C7: Soul Energy Tier | D7: Char | F7: Soul Energy Tier | G7: Akemi | H7: Jonem
A8: =RAW!$A$6 -> 400 | C8: Tier I | D8: =($A8/D$5)/365 -> 1.0958904 | F8: Tier I | G8: =($A8/G$5)/365 -> 0.10958904 | H8: =($A8/H$5)/365 -> 0.091324201 | I8: =($A8/I$5)/365 -> 1.0958904 | J8: =($A8/J$5)/365 -> 1.0958904 | K8: =($A8/K$5)/365 -> 1.0958904 | L8: =($A8/L$5)/365 -> 1.0958904 | M8: =($A8/M$5)/365 -> 1.0958904 | N8: =($A8/N$5)/365 -> 1.0958904 | ... AB8: =($A8/AB$5)/365 -> 1.0958904
A9: =RAW!$A$7 -> 1200 | C9: Tier II | D9: =($A9/D$5)/365 -> 3.2876712 | F9: Tier II | G9: =($A9/G$5)/365 -> 0.32876712 | H9: =($A9/H$5)/365 -> 0.2739726 | I9: =($A9/I$5)/365 -> 3.2876712 | J9: =($A9/J$5)/365 -> 3.2876712 | K9: =($A9/K$5)/365 -> 3.2876712 | L9: =($A9/L$5)/365 -> 3.2876712 | M9: =($A9/M$5)/365 -> 3.2876712 | N9: =($A9/N$5)/365 -> 3.2876712 | ... AB9: =($A9/AB$5)/365 -> 3.2876712
A10: =RAW!$A$8 -> 2800 | C10: Tier III | D10: =($A10/D$5)/365 -> 7.6712329 | F10: Tier III | G10: =($A10/G$5)/365 -> 0.76712329 | H10: =($A10/H$5)/365 -> 0.63926941 | I10: =($A10/I$5)/365 -> 7.6712329 | J10: =($A10/J$5)/365 -> 7.6712329 | K10: =($A10/K$5)/365 -> 7.6712329 | L10: =($A10/L$5)/365 -> 7.6712329 | M10: =($A10/M$5)/365 -> 7.6712329 | N10: =($A10/N$5)/365 -> 7.6712329 | ... AB10: =($A10/AB$5)/365 -> 7.6712329
A11: =RAW!$A$9 -> 6000 | C11: Tier IV | D11: =($A11/D$5)/365 -> 16.438356 | F11: Tier IV | G11: =($A11/G$5)/365 -> 1.6438356 | H11: =($A11/H$5)/365 -> 1.369863 | I11: =($A11/I$5)/365 -> 16.438356 | J11: =($A11/J$5)/365 -> 16.438356 | K11: =($A11/K$5)/365 -> 16.438356 | L11: =($A11/L$5)/365 -> 16.438356 | M11: =($A11/M$5)/365 -> 16.438356 | N11: =($A11/N$5)/365 -> 16.438356 | ... AB11: =($A11/AB$5)/365 -> 16.438356
A12: =RAW!$A$10 -> 12400 | C12: Tier V | D12: =($A12/D$5)/365 -> 33.972603 | F12: Tier V | G12: =($A12/G$5)/365 -> 3.3972603 | H12: =($A12/H$5)/365 -> 2.8310502 | I12: =($A12/I$5)/365 -> 33.972603 | J12: =($A12/J$5)/365 -> 33.972603 | K12: =($A12/K$5)/365 -> 33.972603 | L12: =($A12/L$5)/365 -> 33.972603 | M12: =($A12/M$5)/365 -> 33.972603 | N12: =($A12/N$5)/365 -> 33.972603 | ... AB12: =($A12/AB$5)/365 -> 33.972603
A13: =RAW!$A$11 -> 25200 | C13: Tier VI | D13: =($A13/D$5)/365 -> 69.041096 | F13: Tier VI | G13: =($A13/G$5)/365 -> 6.9041096 | H13: =($A13/H$5)/365 -> 5.7534247 | I13: =($A13/I$5)/365 -> 69.041096 | J13: =($A13/J$5)/365 -> 69.041096 | K13: =($A13/K$5)/365 -> 69.041096 | L13: =($A13/L$5)/365 -> 69.041096 | M13: =($A13/M$5)/365 -> 69.041096 | N13: =($A13/N$5)/365 -> 69.041096 | ... AB13: =($A13/AB$5)/365 -> 69.041096
A14: =RAW!$A$12 -> 50800 | C14: Tier VII | D14: =($A14/D$5)/365 -> 139.17808 | F14: Tier VII | G14: =($A14/G$5)/365 -> 13.917808 | H14: =($A14/H$5)/365 -> 11.598174 | I14: =($A14/I$5)/365 -> 139.17808 | J14: =($A14/J$5)/365 -> 139.17808 | K14: =($A14/K$5)/365 -> 139.17808 | L14: =($A14/L$5)/365 -> 139.17808 | M14: =($A14/M$5)/365 -> 139.17808 | N14: =($A14/N$5)/365 -> 139.17808 | ... AB14: =($A14/AB$5)/365 -> 139.17808
A15: =RAW!$A$13 -> 102000 | C15: Tier VIII | D15: =($A15/D$5)/365 -> 279.45205 | F15: Tier VIII | G15: =($A15/G$5)/365 -> 27.945205 | H15: =($A15/H$5)/365 -> 23.287671 | I15: =($A15/I$5)/365 -> 279.45205 | J15: =($A15/J$5)/365 -> 279.45205 | K15: =($A15/K$5)/365 -> 279.45205 | L15: =($A15/L$5)/365 -> 279.45205 | M15: =($A15/M$5)/365 -> 279.45205 | N15: =($A15/N$5)/365 -> 279.45205 | ... AB15: =($A15/AB$5)/365 -> 279.45205
A16: =RAW!$A$14 -> 204400 | C16: Tier IX | D16: =($A16/D$5)/365 -> 560 | F16: Tier IX | G16: =($A16/G$5)/365 -> 56 | H16: =($A16/H$5)/365 -> 46.666667 | I16: =($A16/I$5)/365 -> 560 | J16: =($A16/J$5)/365 -> 560 | K16: =($A16/K$5)/365 -> 560 | L16: =($A16/L$5)/365 -> 560 | M16: =($A16/M$5)/365 -> 560 | N16: =($A16/N$5)/365 -> 560 | ... AB16: =($A16/AB$5)/365 -> 560
A17: =RAW!$A$15 -> 409200 | C17: Tier X | D17: =($A17/D$5)/365 -> 1121.0959 | F17: Tier X | G17: =($A17/G$5)/365 -> 112.10959 | H17: =($A17/H$5)/365 -> 93.424658 | I17: =($A17/I$5)/365 -> 1121.0959 | J17: =($A17/J$5)/365 -> 1121.0959 | K17: =($A17/K$5)/365 -> 1121.0959 | L17: =($A17/L$5)/365 -> 1121.0959 | M17: =($A17/M$5)/365 -> 1121.0959 | N17: =($A17/N$5)/365 -> 1121.0959 | ... AB17: =($A17/AB$5)/365 -> 1121.0959
A18: =RAW!$A$16 -> 818800 | C18: Tier XI | D18: =($A18/D$5)/365 -> 2243.2877 | F18: Tier XI | G18: =($A18/G$5)/365 -> 224.32877 | H18: =($A18/H$5)/365 -> 186.94064 | I18: =($A18/I$5)/365 -> 2243.2877 | J18: =($A18/J$5)/365 -> 2243.2877 | K18: =($A18/K$5)/365 -> 2243.2877 | L18: =($A18/L$5)/365 -> 2243.2877 | M18: =($A18/M$5)/365 -> 2243.2877 | N18: =($A18/N$5)/365 -> 2243.2877 | ... AB18: =($A18/AB$5)/365 -> 2243.2877
A19: =RAW!$A$17 -> 1638000 | C19: Tier XII | D19: =($A19/D$5)/365 -> 4487.6712 | F19: Tier XII | G19: =($A19/G$5)/365 -> 448.76712 | H19: =($A19/H$5)/365 -> 373.9726 | I19: =($A19/I$5)/365 -> 4487.6712 | J19: =($A19/J$5)/365 -> 4487.6712 | K19: =($A19/K$5)/365 -> 4487.6712 | L19: =($A19/L$5)/365 -> 4487.6712 | M19: =($A19/M$5)/365 -> 4487.6712 | N19: =($A19/N$5)/365 -> 4487.6712 | ... AB19: =($A19/AB$5)/365 -> 4487.6712
A20: =RAW!$A$18 -> 3276400 | C20: Tier XIII | D20: =($A20/D$5)/365 -> 8976.4384 | F20: Tier XIII | G20: =($A20/G$5)/365 -> 897.64384 | H20: =($A20/H$5)/365 -> 748.03653 | I20: =($A20/I$5)/365 -> 8976.4384 | J20: =($A20/J$5)/365 -> 8976.4384 | K20: =($A20/K$5)/365 -> 8976.4384 | L20: =($A20/L$5)/365 -> 8976.4384 | M20: =($A20/M$5)/365 -> 8976.4384 | N20: =($A20/N$5)/365 -> 8976.4384 | ... AB20: =($A20/AB$5)/365 -> 8976.4384
A21: =RAW!$A$19 -> 6553200 | C21: Tier XIV | D21: =($A21/D$5)/365 -> 17953.973 | F21: Tier XIV | G21: =($A21/G$5)/365 -> 1795.3973 | H21: =($A21/H$5)/365 -> 1496.1644 | I21: =($A21/I$5)/365 -> 17953.973 | J21: =($A21/J$5)/365 -> 17953.973 | K21: =($A21/K$5)/365 -> 17953.973 | L21: =($A21/L$5)/365 -> 17953.973 | M21: =($A21/M$5)/365 -> 17953.973 | N21: =($A21/N$5)/365 -> 17953.973 | ... AB21: =($A21/AB$5)/365 -> 17953.973
A22: =RAW!$A$20 -> 13106800 | C22: Tier XV | D22: =($A22/D$5)/365 -> 35909.041 | F22: Tier XV | G22: =($A22/G$5)/365 -> 3590.9041 | H22: =($A22/H$5)/365 -> 2992.4201 | I22: =($A22/I$5)/365 -> 35909.041 | J22: =($A22/J$5)/365 -> 35909.041 | K22: =($A22/K$5)/365 -> 35909.041 | L22: =($A22/L$5)/365 -> 35909.041 | M22: =($A22/M$5)/365 -> 35909.041 | N22: =($A22/N$5)/365 -> 35909.041 | ... AB22: =($A22/AB$5)/365 -> 35909.041
A23: =RAW!$A$21 -> 26214000 | C23: Tier XVI | D23: =($A23/D$5)/365 -> 71819.178 | F23: Tier XVI | G23: =($A23/G$5)/365 -> 7181.9178 | H23: =($A23/H$5)/365 -> 5984.9315 | I23: =($A23/I$5)/365 -> 71819.178 | J23: =($A23/J$5)/365 -> 71819.178 | K23: =($A23/K$5)/365 -> 71819.178 | L23: =($A23/L$5)/365 -> 71819.178 | M23: =($A23/M$5)/365 -> 71819.178 | N23: =($A23/N$5)/365 -> 71819.178 | ... AB23: =($A23/AB$5)/365 -> 71819.178
A24: =RAW!$A$22 -> 52428400 | C24: Tier XVII | D24: =($A24/D$5)/365 -> 143639.45 | F24: Tier XVII | G24: =($A24/G$5)/365 -> 14363.945 | H24: =($A24/H$5)/365 -> 11969.954 | I24: =($A24/I$5)/365 -> 143639.45 | J24: =($A24/J$5)/365 -> 143639.45 | K24: =($A24/K$5)/365 -> 143639.45 | L24: =($A24/L$5)/365 -> 143639.45 | M24: =($A24/M$5)/365 -> 143639.45 | N24: =($A24/N$5)/365 -> 143639.45 | ... AB24: =($A24/AB$5)/365 -> 143639.45
G25: How Many days does it take to recharge a spell
A26: Spell Soul Cost | C26: Soul Energy Tier | D26: Char | F26: Soul Energy Tier | G26: =G7 -> Akemi | H26: =H7 -> Jonem | I26: =I7 -> 0 | J26: =J7 -> 0 | K26: =K7 -> 0 | L26: =L7 -> 0 | M26: =M7 -> 0 | N26: =N7 -> 0 | ... AB26: =AB7 -> 0
A27: =RAW!$A$6 -> 400 | C27: Tier I | D27: =$A27/D$5 -> 400 | F27: Tier I | G27: =$A27/G$5 -> 40 | H27: =$A27/H$5 -> 33.333333 | I27: =$A27/I$5 -> 400 | J27: =$A27/J$5 -> 400 | K27: =$A27/K$5 -> 400 | L27: =$A27/L$5 -> 400 | M27: =$A27/M$5 -> 400 | N27: =$A27/N$5 -> 400 | ... AB27: =$A27/AB$5 -> 400
A28: =RAW!$A$7 -> 1200 | C28: Tier II | D28: =$A28/D$5 -> 1200 | F28: Tier II | G28: =$A28/G$5 -> 120 | H28: =$A28/H$5 -> 100 | I28: =$A28/I$5 -> 1200 | J28: =$A28/J$5 -> 1200 | K28: =$A28/K$5 -> 1200 | L28: =$A28/L$5 -> 1200 | M28: =$A28/M$5 -> 1200 | N28: =$A28/N$5 -> 1200 | ... AB28: =$A28/AB$5 -> 1200
A29: =RAW!$A$8 -> 2800 | C29: Tier III | D29: =$A29/D$5 -> 2800 | F29: Tier III | G29: =$A29/G$5 -> 280 | H29: =$A29/H$5 -> 233.33333 | I29: =$A29/I$5 -> 2800 | J29: =$A29/J$5 -> 2800 | K29: =$A29/K$5 -> 2800 | L29: =$A29/L$5 -> 2800 | M29: =$A29/M$5 -> 2800 | N29: =$A29/N$5 -> 2800 | ... AB29: =$A29/AB$5 -> 2800
A30: =RAW!$A$9 -> 6000 | C30: Tier IV | D30: =$A30/D$5 -> 6000 | F30: Tier IV | G30: =$A30/G$5 -> 600 | H30: =$A30/H$5 -> 500 | I30: =$A30/I$5 -> 6000 | J30: =$A30/J$5 -> 6000 | K30: =$A30/K$5 -> 6000 | L30: =$A30/L$5 -> 6000 | M30: =$A30/M$5 -> 6000 | N30: =$A30/N$5 -> 6000 | ... AB30: =$A30/AB$5 -> 6000
A31: =RAW!$A$10 -> 12400 | C31: Tier V | D31: =$A31/D$5 -> 12400 | F31: Tier V | G31: =$A31/G$5 -> 1240 | H31: =$A31/H$5 -> 1033.3333 | I31: =$A31/I$5 -> 12400 | J31: =$A31/J$5 -> 12400 | K31: =$A31/K$5 -> 12400 | L31: =$A31/L$5 -> 12400 | M31: =$A31/M$5 -> 12400 | N31: =$A31/N$5 -> 12400 | ... AB31: =$A31/AB$5 -> 12400
A32: =RAW!$A$11 -> 25200 | C32: Tier VI | D32: =$A32/D$5 -> 25200 | F32: Tier VI | G32: =$A32/G$5 -> 2520 | H32: =$A32/H$5 -> 2100 | I32: =$A32/I$5 -> 25200 | J32: =$A32/J$5 -> 25200 | K32: =$A32/K$5 -> 25200 | L32: =$A32/L$5 -> 25200 | M32: =$A32/M$5 -> 25200 | N32: =$A32/N$5 -> 25200 | ... AB32: =$A32/AB$5 -> 25200
A33: =RAW!$A$12 -> 50800 | C33: Tier VII | D33: =$A33/D$5 -> 50800 | F33: Tier VII | G33: =$A33/G$5 -> 5080 | H33: =$A33/H$5 -> 4233.3333 | I33: =$A33/I$5 -> 50800 | J33: =$A33/J$5 -> 50800 | K33: =$A33/K$5 -> 50800 | L33: =$A33/L$5 -> 50800 | M33: =$A33/M$5 -> 50800 | N33: =$A33/N$5 -> 50800 | ... AB33: =$A33/AB$5 -> 50800
A34: =RAW!$A$13 -> 102000 | C34: Tier VIII | D34: =$A34/D$5 -> 102000 | F34: Tier VIII | G34: =$A34/G$5 -> 10200 | H34: =$A34/H$5 -> 8500 | I34: =$A34/I$5 -> 102000 | J34: =$A34/J$5 -> 102000 | K34: =$A34/K$5 -> 102000 | L34: =$A34/L$5 -> 102000 | M34: =$A34/M$5 -> 102000 | N34: =$A34/N$5 -> 102000 | ... AB34: =$A34/AB$5 -> 102000
A35: =RAW!$A$14 -> 204400 | C35: Tier IX | D35: =$A35/D$5 -> 204400 | F35: Tier IX | G35: =$A35/G$5 -> 20440 | H35: =$A35/H$5 -> 17033.333 | I35: =$A35/I$5 -> 204400 | J35: =$A35/J$5 -> 204400 | K35: =$A35/K$5 -> 204400 | L35: =$A35/L$5 -> 204400 | M35: =$A35/M$5 -> 204400 | N35: =$A35/N$5 -> 204400 | ... AB35: =$A35/AB$5 -> 204400
A36: =RAW!$A$15 -> 409200 | C36: Tier X | D36: =$A36/D$5 -> 409200 | F36: Tier X | G36: =$A36/G$5 -> 40920 | H36: =$A36/H$5 -> 34100 | I36: =$A36/I$5 -> 409200 | J36: =$A36/J$5 -> 409200 | K36: =$A36/K$5 -> 409200 | L36: =$A36/L$5 -> 409200 | M36: =$A36/M$5 -> 409200 | N36: =$A36/N$5 -> 409200 | ... AB36: =$A36/AB$5 -> 409200
A37: =RAW!$A$16 -> 818800 | C37: Tier XI | D37: =$A37/D$5 -> 818800 | F37: Tier XI | G37: =$A37/G$5 -> 81880 | H37: =$A37/H$5 -> 68233.333 | I37: =$A37/I$5 -> 818800 | J37: =$A37/J$5 -> 818800 | K37: =$A37/K$5 -> 818800 | L37: =$A37/L$5 -> 818800 | M37: =$A37/M$5 -> 818800 | N37: =$A37/N$5 -> 818800 | ... AB37: =$A37/AB$5 -> 818800
A38: =RAW!$A$17 -> 1638000 | C38: Tier XII | D38: =$A38/D$5 -> 1638000 | F38: Tier XII | G38: =$A38/G$5 -> 163800 | H38: =$A38/H$5 -> 136500 | I38: =$A38/I$5 -> 1638000 | J38: =$A38/J$5 -> 1638000 | K38: =$A38/K$5 -> 1638000 | L38: =$A38/L$5 -> 1638000 | M38: =$A38/M$5 -> 1638000 | N38: =$A38/N$5 -> 1638000 | ... AB38: =$A38/AB$5 -> 1638000
A39: =RAW!$A$18 -> 3276400 | C39: Tier XIII | D39: =$A39/D$5 -> 3276400 | F39: Tier XIII | G39: =$A39/G$5 -> 327640 | H39: =$A39/H$5 -> 273033.33 | I39: =$A39/I$5 -> 3276400 | J39: =$A39/J$5 -> 3276400 | K39: =$A39/K$5 -> 3276400 | L39: =$A39/L$5 -> 3276400 | M39: =$A39/M$5 -> 3276400 | N39: =$A39/N$5 -> 3276400 | ... AB39: =$A39/AB$5 -> 3276400
A40: =RAW!$A$19 -> 6553200 | C40: Tier XIV | D40: =$A40/D$5 -> 6553200 | F40: Tier XIV | G40: =$A40/G$5 -> 655320 | H40: =$A40/H$5 -> 546100 | I40: =$A40/I$5 -> 6553200 | J40: =$A40/J$5 -> 6553200 | K40: =$A40/K$5 -> 6553200 | L40: =$A40/L$5 -> 6553200 | M40: =$A40/M$5 -> 6553200 | N40: =$A40/N$5 -> 6553200 | ... AB40: =$A40/AB$5 -> 6553200
...

Sheet Flatland
C1: CHAR CALC | G1: FAUNA (HERBIVORES) AVERAGE
A2: Below Child years is equals to shares of parents soul being infused | C2: Child | D2: =D3/12 -> 0.018939394 | F2: Child | G2: =G3/12 -> 1.7045455 | H2: =H3/12 -> 1.7045455 | I2: =I3/12 -> 1.3257576 | J2: =J3/12 -> 2.2916667 | K2: =K3/12 -> 0.9280303 | L2: =L3/12 -> 0.018939394 | M2: =M3/12 -> 0.018939394 | N2: =N3/12 -> 0.018939394 | ... AB2: =AB3/12 -> 0.018939394
C3: Adulthood | D3: =D4/4.4 -> 0.22727273 | F3: Adulthood | G3: =G4/4.4 -> 20.454545 | H3: =H4/4.4 -> 20.454545 | I3: =I4/4.4 -> 15.909091 | J3: =J4/4.4 -> 27.5 | K3: =K4/4.4 -> 11.136364 | L3: =L4/4.4 -> 0.22727273 | M3: =M4/4.4 -> 0.22727273 | N3: =N4/4.4 -> 0.22727273 | ... AB3: =AB4/4.4 -> 0.22727273
C4: Lifespan | D4: 1 | F4: Lifespan | G4: 90 | H4: 90 | I4: 70 | J4: 121 | K4: 49 | L4: 1 | M4: 1 | N4: 1 | O4: 1 | P4: 1 | Q4: 1 | R4: 1 | S4: 1 | T4: 1 | U4: 1 | V4: 1 | W4: 1 | X4: 1 | Y4: 1 | Z4: 1 | AA4: 1 | AB4: 1
C5: Soul Recharge/Day | D5: 1 | F5: Soul Recharge/Day | G5: 15 | H5: 15 | I5: 10 | J5: 14 | K5: 60 | L5: 1 | M5: 1 | N5: 1 | O5: 1 | P5: 1 | Q5: 1 | R5: 1 | S5: 1 | T5: 1 | U5: 1 | V5: 1 | W5: 1 | X5: 1 | Y5: 1 | Z5: 1 | AA5: 1 | AB5: 1
G6: Average Total Years to Reach Tier
A7: Accumulative Total Cost | C7: Soul Energy Tier | D7: Char | F7: Soul Energy Tier | G7: Katsuki | H7: Katsumi | I7: Ryo | J7: Hanako | K7: Mimi
A8: =RAW!$A$6 -> 400 | C8: Tier I | D8: =($A8/D$5)/365 -> 1.0958904 | F8: Tier I | G8: =($A8/G$5)/365 -> 0.073059361 | H8: =($A8/H$5)/365 -> 0.073059361 | I8: =($A8/I$5)/365 -> 0.10958904 | J8: =($A8/J$5)/365 -> 0.078277886 | K8: =($A8/K$5)/365 -> 0.01826484 | L8: =($A8/L$5)/365 -> 1.0958904 | M8: =($A8/M$5)/365 -> 1.0958904 | N8: =($A8/N$5)/365 -> 1.0958904 | ... AB8: =($A8/AB$5)/365 -> 1.0958904
A9: =RAW!$A$7 -> 1200 | C9: Tier II | D9: =($A9/D$5)/365 -> 3.2876712 | F9: Tier II | G9: =($A9/G$5)/365 -> 0.21917808 | H9: =($A9/H$5)/365 -> 0.21917808 | I9: =($A9/I$5)/365 -> 0.32876712 | J9: =($A9/J$5)/365 -> 0.23483366 | K9: =($A9/K$5)/365 -> 0.054794521 | L9: =($A9/L$5)/365 -> 3.2876712 | M9: =($A9/M$5)/365 -> 3.2876712 | N9: =($A9/N$5)/365 -> 3.2876712 | ... AB9: =($A9/AB$5)/365 -> 3.2876712
A10: =RAW!$A$8 -> 2800 | C10: Tier III | D10: =($A10/D$5)/365 -> 7.6712329 | F10: Tier III | G10: =($A10/G$5)/365 -> 0.51141553 | H10: =($A10/H$5)/365 -> 0.51141553 | I10: =($A10/I$5)/365 -> 0.76712329 | J10: =($A10/J$5)/365 -> 0.54794521 | K10: =($A10/K$5)/365 -> 0.12785388 | L10: =($A10/L$5)/365 -> 7.6712329 | M10: =($A10/M$5)/365 -> 7.6712329 | N10: =($A10/N$5)/365 -> 7.6712329 | ... AB10: =($A10/AB$5)/365 -> 7.6712329
A11: =RAW!$A$9 -> 6000 | C11: Tier IV | D11: =($A11/D$5)/365 -> 16.438356 | F11: Tier IV | G11: =($A11/G$5)/365 -> 1.0958904 | H11: =($A11/H$5)/365 -> 1.0958904 | I11: =($A11/I$5)/365 -> 1.6438356 | J11: =($A11/J$5)/365 -> 1.1741683 | K11: =($A11/K$5)/365 -> 0.2739726 | L11: =($A11/L$5)/365 -> 16.438356 | M11: =($A11/M$5)/365 -> 16.438356 | N11: =($A11/N$5)/365 -> 16.438356 | ... AB11: =($A11/AB$5)/365 -> 16.438356
A12: =RAW!$A$10 -> 12400 | C12: Tier V | D12: =($A12/D$5)/365 -> 33.972603 | F12: Tier V | G12: =($A12/G$5)/365 -> 2.2648402 | H12: =($A12/H$5)/365 -> 2.2648402 | I12: =($A12/I$5)/365 -> 3.3972603 | J12: =($A12/J$5)/365 -> 2.4266145 | K12: =($A12/K$5)/365 -> 0.56621005 | L12: =($A12/L$5)/365 -> 33.972603 | M12: =($A12/M$5)/365 -> 33.972603 | N12: =($A12/N$5)/365 -> 33.972603 | ... AB12: =($A12/AB$5)/365 -> 33.972603
A13: =RAW!$A$11 -> 25200 | C13: Tier VI | D13: =($A13/D$5)/365 -> 69.041096 | F13: Tier VI | G13: =($A13/G$5)/365 -> 4.6027397 | H13: =($A13/H$5)/365 -> 4.6027397 | I13: =($A13/I$5)/365 -> 6.9041096 | J13: =($A13/J$5)/365 -> 4.9315068 | K13: =($A13/K$5)/365 -> 1.1506849 | L13: =($A13/L$5)/365 -> 69.041096 | M13: =($A13/M$5)/365 -> 69.041096 | N13: =($A13/N$5)/365 -> 69.041096 | ... AB13: =($A13/AB$5)/365 -> 69.041096
A14: =RAW!$A$12 -> 50800 | C14: Tier VII | D14: =($A14/D$5)/365 -> 139.17808 | F14: Tier VII | G14: =($A14/G$5)/365 -> 9.2785388 | H14: =($A14/H$5)/365 -> 9.2785388 | I14: =($A14/I$5)/365 -> 13.917808 | J14: =($A14/J$5)/365 -> 9.9412916 | K14: =($A14/K$5)/365 -> 2.3196347 | L14: =($A14/L$5)/365 -> 139.17808 | M14: =($A14/M$5)/365 -> 139.17808 | N14: =($A14/N$5)/365 -> 139.17808 | ... AB14: =($A14/AB$5)/365 -> 139.17808
A15: =RAW!$A$13 -> 102000 | C15: Tier VIII | D15: =($A15/D$5)/365 -> 279.45205 | F15: Tier VIII | G15: =($A15/G$5)/365 -> 18.630137 | H15: =($A15/H$5)/365 -> 18.630137 | I15: =($A15/I$5)/365 -> 27.945205 | J15: =($A15/J$5)/365 -> 19.960861 | K15: =($A15/K$5)/365 -> 4.6575342 | L15: =($A15/L$5)/365 -> 279.45205 | M15: =($A15/M$5)/365 -> 279.45205 | N15: =($A15/N$5)/365 -> 279.45205 | ... AB15: =($A15/AB$5)/365 -> 279.45205
A16: =RAW!$A$14 -> 204400 | C16: Tier IX | D16: =($A16/D$5)/365 -> 560 | F16: Tier IX | G16: =($A16/G$5)/365 -> 37.333333 | H16: =($A16/H$5)/365 -> 37.333333 | I16: =($A16/I$5)/365 -> 56 | J16: =($A16/J$5)/365 -> 40 | K16: =($A16/K$5)/365 -> 9.3333333 | L16: =($A16/L$5)/365 -> 560 | M16: =($A16/M$5)/365 -> 560 | N16: =($A16/N$5)/365 -> 560 | ... AB16: =($A16/AB$5)/365 -> 560
A17: =RAW!$A$15 -> 409200 | C17: Tier X | D17: =($A17/D$5)/365 -> 1121.0959 | F17: Tier X | G17: =($A17/G$5)/365 -> 74.739726 | H17: =($A17/H$5)/365 -> 74.739726 | I17: =($A17/I$5)/365 -> 112.10959 | J17: =($A17/J$5)/365 -> 80.078278 | K17: =($A17/K$5)/365 -> 18.684932 | L17: =($A17/L$5)/365 -> 1121.0959 | M17: =($A17/M$5)/365 -> 1121.0959 | N17: =($A17/N$5)/365 -> 1121.0959 | ... AB17: =($A17/AB$5)/365 -> 1121.0959
A18: =RAW!$A$16 -> 818800 | C18: Tier XI | D18: =($A18/D$5)/365 -> 2243.2877 | F18: Tier XI | G18: =($A18/G$5)/365 -> 149.55251 | H18: =($A18/H$5)/365 -> 149.55251 | I18: =($A18/I$5)/365 -> 224.32877 | J18: =($A18/J$5)/365 -> 160.23483 | K18: =($A18/K$5)/365 -> 37.388128 | L18: =($A18/L$5)/365 -> 2243.2877 | M18: =($A18/M$5)/365 -> 2243.2877 | N18: =($A18/N$5)/365 -> 2243.2877 | ... AB18: =($A18/AB$5)/365 -> 2243.2877
A19: =RAW!$A$17 -> 1638000 | C19: Tier XII | D19: =($A19/D$5)/365 -> 4487.6712 | F19: Tier XII | G19: =($A19/G$5)/365 -> 299.17808 | H19: =($A19/H$5)/365 -> 299.17808 | I19: =($A19/I$5)/365 -> 448.76712 | J19: =($A19/J$5)/365 -> 320.54795 | K19: =($A19/K$5)/365 -> 74.794521 | L19: =($A19/L$5)/365 -> 4487.6712 | M19: =($A19/M$5)/365 -> 4487.6712 | N19: =($A19/N$5)/365 -> 4487.6712 | ... AB19: =($A19/AB$5)/365 -> 4487.6712
A20: =RAW!$A$18 -> 3276400 | C20: Tier XIII | D20: =($A20/D$5)/365 -> 8976.4384 | F20: Tier XIII | G20: =($A20/G$5)/365 -> 598.42922 | H20: =($A20/H$5)/365 -> 598.42922 | I20: =($A20/I$5)/365 -> 897.64384 | J20: =($A20/J$5)/365 -> 641.17417 | K20: =($A20/K$5)/365 -> 149.60731 | L20: =($A20/L$5)/365 -> 8976.4384 | M20: =($A20/M$5)/365 -> 8976.4384 | N20: =($A20/N$5)/365 -> 8976.4384 | ... AB20: =($A20/AB$5)/365 -> 8976.4384
A21: =RAW!$A$19 -> 6553200 | C21: Tier XIV | D21: =($A21/D$5)/365 -> 17953.973 | F21: Tier XIV | G21: =($A21/G$5)/365 -> 1196.9315 | H21: =($A21/H$5)/365 -> 1196.9315 | I21: =($A21/I$5)/365 -> 1795.3973 | J21: =($A21/J$5)/365 -> 1282.4266 | K21: =($A21/K$5)/365 -> 299.23288 | L21: =($A21/L$5)/365 -> 17953.973 | M21: =($A21/M$5)/365 -> 17953.973 | N21: =($A21/N$5)/365 -> 17953.973 | ... AB21: =($A21/AB$5)/365 -> 17953.973
A22: =RAW!$A$20 -> 13106800 | C22: Tier XV | D22: =($A22/D$5)/365 -> 35909.041 | F22: Tier XV | G22: =($A22/G$5)/365 -> 2393.9361 | H22: =($A22/H$5)/365 -> 2393.9361 | I22: =($A22/I$5)/365 -> 3590.9041 | J22: =($A22/J$5)/365 -> 2564.9315 | K22: =($A22/K$5)/365 -> 598.48402 | L22: =($A22/L$5)/365 -> 35909.041 | M22: =($A22/M$5)/365 -> 35909.041 | N22: =($A22/N$5)/365 -> 35909.041 | ... AB22: =($A22/AB$5)/365 -> 35909.041
A23: =RAW!$A$21 -> 26214000 | C23: Tier XVI | D23: =($A23/D$5)/365 -> 71819.178 | F23: Tier XVI | G23: =($A23/G$5)/365 -> 4787.9452 | H23: =($A23/H$5)/365 -> 4787.9452 | I23: =($A23/I$5)/365 -> 7181.9178 | J23: =($A23/J$5)/365 -> 5129.9413 | K23: =($A23/K$5)/365 -> 1196.9863 | L23: =($A23/L$5)/365 -> 71819.178 | M23: =($A23/M$5)/365 -> 71819.178 | N23: =($A23/N$5)/365 -> 71819.178 | ... AB23: =($A23/AB$5)/365 -> 71819.178
A24: =RAW!$A$22 -> 52428400 | C24: Tier XVII | D24: =($A24/D$5)/365 -> 143639.45 | F24: Tier XVII | G24: =($A24/G$5)/365 -> 9575.9635 | H24: =($A24/H$5)/365 -> 9575.9635 | I24: =($A24/I$5)/365 -> 14363.945 | J24: =($A24/J$5)/365 -> 10259.961 | K24: =($A24/K$5)/365 -> 2393.9909 | L24: =($A24/L$5)/365 -> 143639.45 | M24: =($A24/M$5)/365 -> 143639.45 | N24: =($A24/N$5)/365 -> 143639.45 | ... AB24: =($A24/AB$5)/365 -> 143639.45
G25: How Many days does it take to recharge a spell
A26: Spell Soul Cost | C26: Soul Energy Tier | D26: Char | F26: Soul Energy Tier | G26: =G7 -> Katsuki | H26: =H7 -> Katsumi | I26: =I7 -> Ryo | J26: =J7 -> Hanako | K26: =K7 -> Mimi | L26: =L7 -> 0 | M26: =M7 -> 0 | N26: =N7 -> 0 | ... AB26: =AB7 -> 0
A27: =RAW!$A$6 -> 400 | C27: Tier I | D27: =$A27/D$5 -> 400 | F27: Tier I | G27: =$A27/G$5 -> 26.666667 | H27: =$A27/H$5 -> 26.666667 | I27: =$A27/I$5 -> 40 | J27: =$A27/J$5 -> 28.571429 | K27: =$A27/K$5 -> 6.6666667 | L27: =$A27/L$5 -> 400 | M27: =$A27/M$5 -> 400 | N27: =$A27/N$5 -> 400 | ... AB27: =$A27/AB$5 -> 400
A28: =RAW!$A$7 -> 1200 | C28: Tier II | D28: =$A28/D$5 -> 1200 | F28: Tier II | G28: =$A28/G$5 -> 80 | H28: =$A28/H$5 -> 80 | I28: =$A28/I$5 -> 120 | J28: =$A28/J$5 -> 85.714286 | K28: =$A28/K$5 -> 20 | L28: =$A28/L$5 -> 1200 | M28: =$A28/M$5 -> 1200 | N28: =$A28/N$5 -> 1200 | ... AB28: =$A28/AB$5 -> 1200
A29: =RAW!$A$8 -> 2800 | C29: Tier III | D29: =$A29/D$5 -> 2800 | F29: Tier III | G29: =$A29/G$5 -> 186.66667 | H29: =$A29/H$5 -> 186.66667 | I29: =$A29/I$5 -> 280 | J29: =$A29/J$5 -> 200 | K29: =$A29/K$5 -> 46.666667 | L29: =$A29/L$5 -> 2800 | M29: =$A29/M$5 -> 2800 | N29: =$A29/N$5 -> 2800 | ... AB29: =$A29/AB$5 -> 2800
A30: =RAW!$A$9 -> 6000 | C30: Tier IV | D30: =$A30/D$5 -> 6000 | F30: Tier IV | G30: =$A30/G$5 -> 400 | H30: =$A30/H$5 -> 400 | I30: =$A30/I$5 -> 600 | J30: =$A30/J$5 -> 428.57143 | K30: =$A30/K$5 -> 100 | L30: =$A30/L$5 -> 6000 | M30: =$A30/M$5 -> 6000 | N30: =$A30/N$5 -> 6000 | ... AB30: =$A30/AB$5 -> 6000
A31: =RAW!$A$10 -> 12400 | C31: Tier V | D31: =$A31/D$5 -> 12400 | F31: Tier V | G31: =$A31/G$5 -> 826.66667 | H31: =$A31/H$5 -> 826.66667 | I31: =$A31/I$5 -> 1240 | J31: =$A31/J$5 -> 885.71429 | K31: =$A31/K$5 -> 206.66667 | L31: =$A31/L$5 -> 12400 | M31: =$A31/M$5 -> 12400 | N31: =$A31/N$5 -> 12400 | ... AB31: =$A31/AB$5 -> 12400
A32: =RAW!$A$11 -> 25200 | C32: Tier VI | D32: =$A32/D$5 -> 25200 | F32: Tier VI | G32: =$A32/G$5 -> 1680 | H32: =$A32/H$5 -> 1680 | I32: =$A32/I$5 -> 2520 | J32: =$A32/J$5 -> 1800 | K32: =$A32/K$5 -> 420 | L32: =$A32/L$5 -> 25200 | M32: =$A32/M$5 -> 25200 | N32: =$A32/N$5 -> 25200 | ... AB32: =$A32/AB$5 -> 25200
A33: =RAW!$A$12 -> 50800 | C33: Tier VII | D33: =$A33/D$5 -> 50800 | F33: Tier VII | G33: =$A33/G$5 -> 3386.6667 | H33: =$A33/H$5 -> 3386.6667 | I33: =$A33/I$5 -> 5080 | J33: =$A33/J$5 -> 3628.5714 | K33: =$A33/K$5 -> 846.66667 | L33: =$A33/L$5 -> 50800 | M33: =$A33/M$5 -> 50800 | N33: =$A33/N$5 -> 50800 | ... AB33: =$A33/AB$5 -> 50800
A34: =RAW!$A$13 -> 102000 | C34: Tier VIII | D34: =$A34/D$5 -> 102000 | F34: Tier VIII | G34: =$A34/G$5 -> 6800 | H34: =$A34/H$5 -> 6800 | I34: =$A34/I$5 -> 10200 | J34: =$A34/J$5 -> 7285.7143 | K34: =$A34/K$5 -> 1700 | L34: =$A34/L$5 -> 102000 | M34: =$A34/M$5 -> 102000 | N34: =$A34/N$5 -> 102000 | ... AB34: =$A34/AB$5 -> 102000
A35: =RAW!$A$14 -> 204400 | C35: Tier IX | D35: =$A35/D$5 -> 204400 | F35: Tier IX | G35: =$A35/G$5 -> 13626.667 | H35: =$A35/H$5 -> 13626.667 | I35: =$A35/I$5 -> 20440 | J35: =$A35/J$5 -> 14600 | K35: =$A35/K$5 -> 3406.6667 | L35: =$A35/L$5 -> 204400 | M35: =$A35/M$5 -> 204400 | N35: =$A35/N$5 -> 204400 | ... AB35: =$A35/AB$5 -> 204400
A36: =RAW!$A$15 -> 409200 | C36: Tier X | D36: =$A36/D$5 -> 409200 | F36: Tier X | G36: =$A36/G$5 -> 27280 | H36: =$A36/H$5 -> 27280 | I36: =$A36/I$5 -> 40920 | J36: =$A36/J$5 -> 29228.571 | K36: =$A36/K$5 -> 6820 | L36: =$A36/L$5 -> 409200 | M36: =$A36/M$5 -> 409200 | N36: =$A36/N$5 -> 409200 | ... AB36: =$A36/AB$5 -> 409200
A37: =RAW!$A$16 -> 818800 | C37: Tier XI | D37: =$A37/D$5 -> 818800 | F37: Tier XI | G37: =$A37/G$5 -> 54586.667 | H37: =$A37/H$5 -> 54586.667 | I37: =$A37/I$5 -> 81880 | J37: =$A37/J$5 -> 58485.714 | K37: =$A37/K$5 -> 13646.667 | L37: =$A37/L$5 -> 818800 | M37: =$A37/M$5 -> 818800 | N37: =$A37/N$5 -> 818800 | ... AB37: =$A37/AB$5 -> 818800
A38: =RAW!$A$17 -> 1638000 | C38: Tier XII | D38: =$A38/D$5 -> 1638000 | F38: Tier XII | G38: =$A38/G$5 -> 109200 | H38: =$A38/H$5 -> 109200 | I38: =$A38/I$5 -> 163800 | J38: =$A38/J$5 -> 117000 | K38: =$A38/K$5 -> 27300 | L38: =$A38/L$5 -> 1638000 | M38: =$A38/M$5 -> 1638000 | N38: =$A38/N$5 -> 1638000 | ... AB38: =$A38/AB$5 -> 1638000
A39: =RAW!$A$18 -> 3276400 | C39: Tier XIII | D39: =$A39/D$5 -> 3276400 | F39: Tier XIII | G39: =$A39/G$5 -> 218426.67 | H39: =$A39/H$5 -> 218426.67 | I39: =$A39/I$5 -> 327640 | J39: =$A39/J$5 -> 234028.57 | K39: =$A39/K$5 -> 54606.667 | L39: =$A39/L$5 -> 3276400 | M39: =$A39/M$5 -> 3276400 | N39: =$A39/N$5 -> 3276400 | ... AB39: =$A39/AB$5 -> 3276400
A40: =RAW!$A$19 -> 6553200 | C40: Tier XIV | D40: =$A40/D$5 -> 6553200 | F40: Tier XIV | G40: =$A40/G$5 -> 436880 | H40: =$A40/H$5 -> 436880 | I40: =$A40/I$5 -> 655320 | J40: =$A40/J$5 -> 468085.71 | K40: =$A40/K$5 -> 109220 | L40: =$A40/L$5 -> 6553200 | M40: =$A40/M$5 -> 6553200 | N40: =$A40/N$5 -> 6553200 | ... AB40: =$A40/AB$5 -> 6553200
...

Sheet Forway
C1: CHAR CALC | G1: FAUNA (HERBIVORES) AVERAGE
A2: Below Child years is equals to shares of parents soul being infused | C2: Child | D2: =D3/12 -> 0.018939394 | F2: Child | G2: =G3/12 -> 9.469697 | H2: =H3/12 -> 1.4204545 | I2: =I3/12 -> 1.8371212 | J2: =J3/12 -> 0.018939394 | K2: =K3/12 -> 5.1893939 | L2: =L3/12 -> 1.5530303 | M2: =M3/12 -> 0.018939394 | N2: =N3/12 -> 0.018939394 | ... AB2: =AB3/12 -> 0.018939394
C3: Adulthood | D3: =D4/4.4 -> 0.22727273 | F3: Adulthood | G3: =G4/4.4 -> 113.63636 | H3: =H4/4.4 -> 17.045455 | I3: =I4/4.4 -> 22.045455 | J3: =J4/4.4 -> 0.22727273 | K3: =K4/4.4 -> 62.272727 | L3: =L4/4.4 -> 18.636364 | M3: =M4/4.4 -> 0.22727273 | N3: =N4/4.4 -> 0.22727273 | ... AB3: =AB4/4.4 -> 0.22727273
C4: Lifespan | D4: 1 | F4: Lifespan | G4: 500 | H4: 75 | I4: 97 | J4: 1 | K4: 274 | L4: 82 | M4: 1 | N4: 1 | O4: 1 | P4: 1 | Q4: 1 | R4: 1 | S4: 1 | T4: 1 | U4: 1 | V4: 1 | W4: 1 | X4: 1 | Y4: 1 | Z4: 1 | AA4: 1 | AB4: 1
C5: Soul Recharge/Day | D5: 1 | F5: Soul Recharge/Day | G5: 30 | H5: 4 | I5: 18 | J5: 1 | K5: 9 | L5: 4 | M5: 1 | N5: 1 | O5: 1 | P5: 1 | Q5: 1 | R5: 1 | S5: 1 | T5: 1 | U5: 1 | V5: 1 | W5: 1 | X5: 1 | Y5: 1 | Z5: 1 | AA5: 1 | AB5: 1
G6: Average Total Years to Reach Tier
A7: Accumulative Total Cost | C7: Soul Energy Tier | D7: Char | F7: Soul Energy Tier | G7: Kozaku | H7: Laura | I7: Yosuke | J7: Rimir | K7: Francisco | L7: Biny
A8: =RAW!$A$6 -> 400 | C8: Tier I | D8: =($A8/D$5)/365 -> 1.0958904 | F8: Tier I | G8: =($A8/G$5)/365 -> 0.03652968 | H8: =($A8/H$5)/365 -> 0.2739726 | I8: =($A8/I$5)/365 -> 0.060882801 | J8: =($A8/J$5)/365 -> 1.0958904 | K8: =($A8/K$5)/365 -> 0.1217656 | L8: =($A8/L$5)/365 -> 0.2739726 | M8: =($A8/M$5)/365 -> 1.0958904 | N8: =($A8/N$5)/365 -> 1.0958904 | ... AB8: =($A8/AB$5)/365 -> 1.0958904
A9: =RAW!$A$7 -> 1200 | C9: Tier II | D9: =($A9/D$5)/365 -> 3.2876712 | F9: Tier II | G9: =($A9/G$5)/365 -> 0.10958904 | H9: =($A9/H$5)/365 -> 0.82191781 | I9: =($A9/I$5)/365 -> 0.1826484 | J9: =($A9/J$5)/365 -> 3.2876712 | K9: =($A9/K$5)/365 -> 0.3652968 | L9: =($A9/L$5)/365 -> 0.82191781 | M9: =($A9/M$5)/365 -> 3.2876712 | N9: =($A9/N$5)/365 -> 3.2876712 | ... AB9: =($A9/AB$5)/365 -> 3.2876712
A10: =RAW!$A$8 -> 2800 | C10: Tier III | D10: =($A10/D$5)/365 -> 7.6712329 | F10: Tier III | G10: =($A10/G$5)/365 -> 0.25570776 | H10: =($A10/H$5)/365 -> 1.9178082 | I10: =($A10/I$5)/365 -> 0.4261796 | J10: =($A10/J$5)/365 -> 7.6712329 | K10: =($A10/K$5)/365 -> 0.85235921 | L10: =($A10/L$5)/365 -> 1.9178082 | M10: =($A10/M$5)/365 -> 7.6712329 | N10: =($A10/N$5)/365 -> 7.6712329 | ... AB10: =($A10/AB$5)/365 -> 7.6712329
A11: =RAW!$A$9 -> 6000 | C11: Tier IV | D11: =($A11/D$5)/365 -> 16.438356 | F11: Tier IV | G11: =($A11/G$5)/365 -> 0.54794521 | H11: =($A11/H$5)/365 -> 4.109589 | I11: =($A11/I$5)/365 -> 0.91324201 | J11: =($A11/J$5)/365 -> 16.438356 | K11: =($A11/K$5)/365 -> 1.826484 | L11: =($A11/L$5)/365 -> 4.109589 | M11: =($A11/M$5)/365 -> 16.438356 | N11: =($A11/N$5)/365 -> 16.438356 | ... AB11: =($A11/AB$5)/365 -> 16.438356
A12: =RAW!$A$10 -> 12400 | C12: Tier V | D12: =($A12/D$5)/365 -> 33.972603 | F12: Tier V | G12: =($A12/G$5)/365 -> 1.1324201 | H12: =($A12/H$5)/365 -> 8.4931507 | I12: =($A12/I$5)/365 -> 1.8873668 | J12: =($A12/J$5)/365 -> 33.972603 | K12: =($A12/K$5)/365 -> 3.7747336 | L12: =($A12/L$5)/365 -> 8.4931507 | M12: =($A12/M$5)/365 -> 33.972603 | N12: =($A12/N$5)/365 -> 33.972603 | ... AB12: =($A12/AB$5)/365 -> 33.972603
A13: =RAW!$A$11 -> 25200 | C13: Tier VI | D13: =($A13/D$5)/365 -> 69.041096 | F13: Tier VI | G13: =($A13/G$5)/365 -> 2.3013699 | H13: =($A13/H$5)/365 -> 17.260274 | I13: =($A13/I$5)/365 -> 3.8356164 | J13: =($A13/J$5)/365 -> 69.041096 | K13: =($A13/K$5)/365 -> 7.6712329 | L13: =($A13/L$5)/365 -> 17.260274 | M13: =($A13/M$5)/365 -> 69.041096 | N13: =($A13/N$5)/365 -> 69.041096 | ... AB13: =($A13/AB$5)/365 -> 69.041096
A14: =RAW!$A$12 -> 50800 | C14: Tier VII | D14: =($A14/D$5)/365 -> 139.17808 | F14: Tier VII | G14: =($A14/G$5)/365 -> 4.6392694 | H14: =($A14/H$5)/365 -> 34.794521 | I14: =($A14/I$5)/365 -> 7.7321157 | J14: =($A14/J$5)/365 -> 139.17808 | K14: =($A14/K$5)/365 -> 15.464231 | L14: =($A14/L$5)/365 -> 34.794521 | M14: =($A14/M$5)/365 -> 139.17808 | N14: =($A14/N$5)/365 -> 139.17808 | ... AB14: =($A14/AB$5)/365 -> 139.17808
A15: =RAW!$A$13 -> 102000 | C15: Tier VIII | D15: =($A15/D$5)/365 -> 279.45205 | F15: Tier VIII | G15: =($A15/G$5)/365 -> 9.3150685 | H15: =($A15/H$5)/365 -> 69.863014 | I15: =($A15/I$5)/365 -> 15.525114 | J15: =($A15/J$5)/365 -> 279.45205 | K15: =($A15/K$5)/365 -> 31.050228 | L15: =($A15/L$5)/365 -> 69.863014 | M15: =($A15/M$5)/365 -> 279.45205 | N15: =($A15/N$5)/365 -> 279.45205 | ... AB15: =($A15/AB$5)/365 -> 279.45205
A16: =RAW!$A$14 -> 204400 | C16: Tier IX | D16: =($A16/D$5)/365 -> 560 | F16: Tier IX | G16: =($A16/G$5)/365 -> 18.666667 | H16: =($A16/H$5)/365 -> 140 | I16: =($A16/I$5)/365 -> 31.111111 | J16: =($A16/J$5)/365 -> 560 | K16: =($A16/K$5)/365 -> 62.222222 | L16: =($A16/L$5)/365 -> 140 | M16: =($A16/M$5)/365 -> 560 | N16: =($A16/N$5)/365 -> 560 | ... AB16: =($A16/AB$5)/365 -> 560
A17: =RAW!$A$15 -> 409200 | C17: Tier X | D17: =($A17/D$5)/365 -> 1121.0959 | F17: Tier X | G17: =($A17/G$5)/365 -> 37.369863 | H17: =($A17/H$5)/365 -> 280.27397 | I17: =($A17/I$5)/365 -> 62.283105 | J17: =($A17/J$5)/365 -> 1121.0959 | K17: =($A17/K$5)/365 -> 124.56621 | L17: =($A17/L$5)/365 -> 280.27397 | M17: =($A17/M$5)/365 -> 1121.0959 | N17: =($A17/N$5)/365 -> 1121.0959 | ... AB17: =($A17/AB$5)/365 -> 1121.0959
A18: =RAW!$A$16 -> 818800 | C18: Tier XI | D18: =($A18/D$5)/365 -> 2243.2877 | F18: Tier XI | G18: =($A18/G$5)/365 -> 74.776256 | H18: =($A18/H$5)/365 -> 560.82192 | I18: =($A18/I$5)/365 -> 124.62709 | J18: =($A18/J$5)/365 -> 2243.2877 | K18: =($A18/K$5)/365 -> 249.25419 | L18: =($A18/L$5)/365 -> 560.82192 | M18: =($A18/M$5)/365 -> 2243.2877 | N18: =($A18/N$5)/365 -> 2243.2877 | ... AB18: =($A18/AB$5)/365 -> 2243.2877
A19: =RAW!$A$17 -> 1638000 | C19: Tier XII | D19: =($A19/D$5)/365 -> 4487.6712 | F19: Tier XII | G19: =($A19/G$5)/365 -> 149.58904 | H19: =($A19/H$5)/365 -> 1121.9178 | I19: =($A19/I$5)/365 -> 249.31507 | J19: =($A19/J$5)/365 -> 4487.6712 | K19: =($A19/K$5)/365 -> 498.63014 | L19: =($A19/L$5)/365 -> 1121.9178 | M19: =($A19/M$5)/365 -> 4487.6712 | N19: =($A19/N$5)/365 -> 4487.6712 | ... AB19: =($A19/AB$5)/365 -> 4487.6712
A20: =RAW!$A$18 -> 3276400 | C20: Tier XIII | D20: =($A20/D$5)/365 -> 8976.4384 | F20: Tier XIII | G20: =($A20/G$5)/365 -> 299.21461 | H20: =($A20/H$5)/365 -> 2244.1096 | I20: =($A20/I$5)/365 -> 498.69102 | J20: =($A20/J$5)/365 -> 8976.4384 | K20: =($A20/K$5)/365 -> 997.38204 | L20: =($A20/L$5)/365 -> 2244.1096 | M20: =($A20/M$5)/365 -> 8976.4384 | N20: =($A20/N$5)/365 -> 8976.4384 | ... AB20: =($A20/AB$5)/365 -> 8976.4384
A21: =RAW!$A$19 -> 6553200 | C21: Tier XIV | D21: =($A21/D$5)/365 -> 17953.973 | F21: Tier XIV | G21: =($A21/G$5)/365 -> 598.46575 | H21: =($A21/H$5)/365 -> 4488.4932 | I21: =($A21/I$5)/365 -> 997.44292 | J21: =($A21/J$5)/365 -> 17953.973 | K21: =($A21/K$5)/365 -> 1994.8858 | L21: =($A21/L$5)/365 -> 4488.4932 | M21: =($A21/M$5)/365 -> 17953.973 | N21: =($A21/N$5)/365 -> 17953.973 | ... AB21: =($A21/AB$5)/365 -> 17953.973
A22: =RAW!$A$20 -> 13106800 | C22: Tier XV | D22: =($A22/D$5)/365 -> 35909.041 | F22: Tier XV | G22: =($A22/G$5)/365 -> 1196.968 | H22: =($A22/H$5)/365 -> 8977.2603 | I22: =($A22/I$5)/365 -> 1994.9467 | J22: =($A22/J$5)/365 -> 35909.041 | K22: =($A22/K$5)/365 -> 3989.8935 | L22: =($A22/L$5)/365 -> 8977.2603 | M22: =($A22/M$5)/365 -> 35909.041 | N22: =($A22/N$5)/365 -> 35909.041 | ... AB22: =($A22/AB$5)/365 -> 35909.041
A23: =RAW!$A$21 -> 26214000 | C23: Tier XVI | D23: =($A23/D$5)/365 -> 71819.178 | F23: Tier XVI | G23: =($A23/G$5)/365 -> 2393.9726 | H23: =($A23/H$5)/365 -> 17954.795 | I23: =($A23/I$5)/365 -> 3989.9543 | J23: =($A23/J$5)/365 -> 71819.178 | K23: =($A23/K$5)/365 -> 7979.9087 | L23: =($A23/L$5)/365 -> 17954.795 | M23: =($A23/M$5)/365 -> 71819.178 | N23: =($A23/N$5)/365 -> 71819.178 | ... AB23: =($A23/AB$5)/365 -> 71819.178
A24: =RAW!$A$22 -> 52428400 | C24: Tier XVII | D24: =($A24/D$5)/365 -> 143639.45 | F24: Tier XVII | G24: =($A24/G$5)/365 -> 4787.9817 | H24: =($A24/H$5)/365 -> 35909.863 | I24: =($A24/I$5)/365 -> 7979.9696 | J24: =($A24/J$5)/365 -> 143639.45 | K24: =($A24/K$5)/365 -> 15959.939 | L24: =($A24/L$5)/365 -> 35909.863 | M24: =($A24/M$5)/365 -> 143639.45 | N24: =($A24/N$5)/365 -> 143639.45 | ... AB24: =($A24/AB$5)/365 -> 143639.45
G25: How Many days does it take to recharge a spell
A26: Spell Soul Cost | C26: Soul Energy Tier | D26: Char | F26: Soul Energy Tier | G26: =G7 -> Kozaku | H26: =H7 -> Laura | I26: =I7 -> Yosuke | J26: =J7 -> Rimir | K26: =K7 -> Francisco | L26: =L7 -> Biny | M26: =M7 -> 0 | N26: =N7 -> 0 | ... AB26: =AB7 -> 0
A27: =RAW!$A$6 -> 400 | C27: Tier I | D27: =$A27/D$5 -> 400 | F27: Tier I | G27: =$A27/G$5 -> 13.333333 | H27: =$A27/H$5 -> 100 | I27: =$A27/I$5 -> 22.222222 | J27: =$A27/J$5 -> 400 | K27: =$A27/K$5 -> 44.444444 | L27: =$A27/L$5 -> 100 | M27: =$A27/M$5 -> 400 | N27: =$A27/N$5 -> 400 | ... AB27: =$A27/AB$5 -> 400
A28: =RAW!$A$7 -> 1200 | C28: Tier II | D28: =$A28/D$5 -> 1200 | F28: Tier II | G28: =$A28/G$5 -> 40 | H28: =$A28/H$5 -> 300 | I28: =$A28/I$5 -> 66.666667 | J28: =$A28/J$5 -> 1200 | K28: =$A28/K$5 -> 133.33333 | L28: =$A28/L$5 -> 300 | M28: =$A28/M$5 -> 1200 | N28: =$A28/N$5 -> 1200 | ... AB28: =$A28/AB$5 -> 1200
A29: =RAW!$A$8 -> 2800 | C29: Tier III | D29: =$A29/D$5 -> 2800 | F29: Tier III | G29: =$A29/G$5 -> 93.333333 | H29: =$A29/H$5 -> 700 | I29: =$A29/I$5 -> 155.55556 | J29: =$A29/J$5 -> 2800 | K29: =$A29/K$5 -> 311.11111 | L29: =$A29/L$5 -> 700 | M29: =$A29/M$5 -> 2800 | N29: =$A29/N$5 -> 2800 | ... AB29: =$A29/AB$5 -> 2800
A30: =RAW!$A$9 -> 6000 | C30: Tier IV | D30: =$A30/D$5 -> 6000 | F30: Tier IV | G30: =$A30/G$5 -> 200 | H30: =$A30/H$5 -> 1500 | I30: =$A30/I$5 -> 333.33333 | J30: =$A30/J$5 -> 6000 | K30: =$A30/K$5 -> 666.66667 | L30: =$A30/L$5 -> 1500 | M30: =$A30/M$5 -> 6000 | N30: =$A30/N$5 -> 6000 | ... AB30: =$A30/AB$5 -> 6000
A31: =RAW!$A$10 -> 12400 | C31: Tier V | D31: =$A31/D$5 -> 12400 | F31: Tier V | G31: =$A31/G$5 -> 413.33333 | H31: =$A31/H$5 -> 3100 | I31: =$A31/I$5 -> 688.88889 | J31: =$A31/J$5 -> 12400 | K31: =$A31/K$5 -> 1377.7778 | L31: =$A31/L$5 -> 3100 | M31: =$A31/M$5 -> 12400 | N31: =$A31/N$5 -> 12400 | ... AB31: =$A31/AB$5 -> 12400
A32: =RAW!$A$11 -> 25200 | C32: Tier VI | D32: =$A32/D$5 -> 25200 | F32: Tier VI | G32: =$A32/G$5 -> 840 | H32: =$A32/H$5 -> 6300 | I32: =$A32/I$5 -> 1400 | J32: =$A32/J$5 -> 25200 | K32: =$A32/K$5 -> 2800 | L32: =$A32/L$5 -> 6300 | M32: =$A32/M$5 -> 25200 | N32: =$A32/N$5 -> 25200 | ... AB32: =$A32/AB$5 -> 25200
A33: =RAW!$A$12 -> 50800 | C33: Tier VII | D33: =$A33/D$5 -> 50800 | F33: Tier VII | G33: =$A33/G$5 -> 1693.3333 | H33: =$A33/H$5 -> 12700 | I33: =$A33/I$5 -> 2822.2222 | J33: =$A33/J$5 -> 50800 | K33: =$A33/K$5 -> 5644.4444 | L33: =$A33/L$5 -> 12700 | M33: =$A33/M$5 -> 50800 | N33: =$A33/N$5 -> 50800 | ... AB33: =$A33/AB$5 -> 50800
A34: =RAW!$A$13 -> 102000 | C34: Tier VIII | D34: =$A34/D$5 -> 102000 | F34: Tier VIII | G34: =$A34/G$5 -> 3400 | H34: =$A34/H$5 -> 25500 | I34: =$A34/I$5 -> 5666.6667 | J34: =$A34/J$5 -> 102000 | K34: =$A34/K$5 -> 11333.333 | L34: =$A34/L$5 -> 25500 | M34: =$A34/M$5 -> 102000 | N34: =$A34/N$5 -> 102000 | ... AB34: =$A34/AB$5 -> 102000
A35: =RAW!$A$14 -> 204400 | C35: Tier IX | D35: =$A35/D$5 -> 204400 | F35: Tier IX | G35: =$A35/G$5 -> 6813.3333 | H35: =$A35/H$5 -> 51100 | I35: =$A35/I$5 -> 11355.556 | J35: =$A35/J$5 -> 204400 | K35: =$A35/K$5 -> 22711.111 | L35: =$A35/L$5 -> 51100 | M35: =$A35/M$5 -> 204400 | N35: =$A35/N$5 -> 204400 | ... AB35: =$A35/AB$5 -> 204400
A36: =RAW!$A$15 -> 409200 | C36: Tier X | D36: =$A36/D$5 -> 409200 | F36: Tier X | G36: =$A36/G$5 -> 13640 | H36: =$A36/H$5 -> 102300 | I36: =$A36/I$5 -> 22733.333 | J36: =$A36/J$5 -> 409200 | K36: =$A36/K$5 -> 45466.667 | L36: =$A36/L$5 -> 102300 | M36: =$A36/M$5 -> 409200 | N36: =$A36/N$5 -> 409200 | ... AB36: =$A36/AB$5 -> 409200
A37: =RAW!$A$16 -> 818800 | C37: Tier XI | D37: =$A37/D$5 -> 818800 | F37: Tier XI | G37: =$A37/G$5 -> 27293.333 | H37: =$A37/H$5 -> 204700 | I37: =$A37/I$5 -> 45488.889 | J37: =$A37/J$5 -> 818800 | K37: =$A37/K$5 -> 90977.778 | L37: =$A37/L$5 -> 204700 | M37: =$A37/M$5 -> 818800 | N37: =$A37/N$5 -> 818800 | ... AB37: =$A37/AB$5 -> 818800
A38: =RAW!$A$17 -> 1638000 | C38: Tier XII | D38: =$A38/D$5 -> 1638000 | F38: Tier XII | G38: =$A38/G$5 -> 54600 | H38: =$A38/H$5 -> 409500 | I38: =$A38/I$5 -> 91000 | J38: =$A38/J$5 -> 1638000 | K38: =$A38/K$5 -> 182000 | L38: =$A38/L$5 -> 409500 | M38: =$A38/M$5 -> 1638000 | N38: =$A38/N$5 -> 1638000 | ... AB38: =$A38/AB$5 -> 1638000
A39: =RAW!$A$18 -> 3276400 | C39: Tier XIII | D39: =$A39/D$5 -> 3276400 | F39: Tier XIII | G39: =$A39/G$5 -> 109213.33 | H39: =$A39/H$5 -> 819100 | I39: =$A39/I$5 -> 182022.22 | J39: =$A39/J$5 -> 3276400 | K39: =$A39/K$5 -> 364044.44 | L39: =$A39/L$5 -> 819100 | M39: =$A39/M$5 -> 3276400 | N39: =$A39/N$5 -> 3276400 | ... AB39: =$A39/AB$5 -> 3276400
A40: =RAW!$A$19 -> 6553200 | C40: Tier XIV | D40: =$A40/D$5 -> 6553200 | F40: Tier XIV | G40: =$A40/G$5 -> 218440 | H40: =$A40/H$5 -> 1638300 | I40: =$A40/I$5 -> 364066.67 | J40: =$A40/J$5 -> 6553200 | K40: =$A40/K$5 -> 728133.33 | L40: =$A40/L$5 -> 1638300 | M40: =$A40/M$5 -> 6553200 | N40: =$A40/N$5 -> 6553200 | ... AB40: =$A40/AB$5 -> 6553200
...

Sheet Forway Villages
C1: CHAR CALC | G1: FAUNA (HERBIVORES) AVERAGE
A2: Below Child years is equals to shares of parents soul being infused | C2: Child | D2: =D3/12 -> 0.018939394 | F2: Child | G2: =G3/12 -> 1.6856061 | H2: =H3/12 -> 1.4772727 | I2: =I3/12 -> 1.5340909 | J2: =J3/12 -> 1.4962121 | K2: =K3/12 -> 1.5151515 | L2: =L3/12 -> 0.018939394 | M2: =M3/12 -> 0.018939394 | N2: =N3/12 -> 0.018939394 | ... AB2: =AB3/12 -> 0.018939394
C3: Adulthood | D3: =D4/4.4 -> 0.22727273 | F3: Adulthood | G3: =G4/4.4 -> 20.227273 | H3: =H4/4.4 -> 17.727273 | I3: =I4/4.4 -> 18.409091 | J3: =J4/4.4 -> 17.954545 | K3: =K4/4.4 -> 18.181818 | L3: =L4/4.4 -> 0.22727273 | M3: =M4/4.4 -> 0.22727273 | N3: =N4/4.4 -> 0.22727273 | ... AB3: =AB4/4.4 -> 0.22727273
C4: Lifespan | D4: 1 | F4: Lifespan | G4: 89 | H4: 78 | I4: 81 | J4: 79 | K4: 80 | L4: 1 | M4: 1 | N4: 1 | O4: 1 | P4: 1 | Q4: 1 | R4: 1 | S4: 1 | T4: 1 | U4: 1 | V4: 1 | W4: 1 | X4: 1 | Y4: 1 | Z4: 1 | AA4: 1 | AB4: 1
C5: Soul Recharge/Day | D5: 1 | F5: Soul Recharge/Day | G5: 9 | H5: 4 | I5: 7 | J5: 5 | K5: 6 | L5: 1 | M5: 1 | N5: 1 | O5: 1 | P5: 1 | Q5: 1 | R5: 1 | S5: 1 | T5: 1 | U5: 1 | V5: 1 | W5: 1 | X5: 1 | Y5: 1 | Z5: 1 | AA5: 1 | AB5: 1
G6: Average Total Years to Reach Tier
A7: Accumulative Total Cost | C7: Soul Energy Tier | D7: Char | F7: Soul Energy Tier | G7: Arukia | H7: Emelia | I7: Nailah | J7: Severino | K7: Vitor
A8: =RAW!$A$6 -> 400 | C8: Tier I | D8: =($A8/D$5)/365 -> 1.0958904 | F8: Tier I | G8: =($A8/G$5)/365 -> 0.1217656 | H8: =($A8/H$5)/365 -> 0.2739726 | I8: =($A8/I$5)/365 -> 0.15655577 | J8: =($A8/J$5)/365 -> 0.21917808 | K8: =($A8/K$5)/365 -> 0.1826484 | L8: =($A8/L$5)/365 -> 1.0958904 | M8: =($A8/M$5)/365 -> 1.0958904 | N8: =($A8/N$5)/365 -> 1.0958904 | ... AB8: =($A8/AB$5)/365 -> 1.0958904
A9: =RAW!$A$7 -> 1200 | C9: Tier II | D9: =($A9/D$5)/365 -> 3.2876712 | F9: Tier II | G9: =($A9/G$5)/365 -> 0.3652968 | H9: =($A9/H$5)/365 -> 0.82191781 | I9: =($A9/I$5)/365 -> 0.46966732 | J9: =($A9/J$5)/365 -> 0.65753425 | K9: =($A9/K$5)/365 -> 0.54794521 | L9: =($A9/L$5)/365 -> 3.2876712 | M9: =($A9/M$5)/365 -> 3.2876712 | N9: =($A9/N$5)/365 -> 3.2876712 | ... AB9: =($A9/AB$5)/365 -> 3.2876712
A10: =RAW!$A$8 -> 2800 | C10: Tier III | D10: =($A10/D$5)/365 -> 7.6712329 | F10: Tier III | G10: =($A10/G$5)/365 -> 0.85235921 | H10: =($A10/H$5)/365 -> 1.9178082 | I10: =($A10/I$5)/365 -> 1.0958904 | J10: =($A10/J$5)/365 -> 1.5342466 | K10: =($A10/K$5)/365 -> 1.2785388 | L10: =($A10/L$5)/365 -> 7.6712329 | M10: =($A10/M$5)/365 -> 7.6712329 | N10: =($A10/N$5)/365 -> 7.6712329 | ... AB10: =($A10/AB$5)/365 -> 7.6712329
A11: =RAW!$A$9 -> 6000 | C11: Tier IV | D11: =($A11/D$5)/365 -> 16.438356 | F11: Tier IV | G11: =($A11/G$5)/365 -> 1.826484 | H11: =($A11/H$5)/365 -> 4.109589 | I11: =($A11/I$5)/365 -> 2.3483366 | J11: =($A11/J$5)/365 -> 3.2876712 | K11: =($A11/K$5)/365 -> 2.739726 | L11: =($A11/L$5)/365 -> 16.438356 | M11: =($A11/M$5)/365 -> 16.438356 | N11: =($A11/N$5)/365 -> 16.438356 | ... AB11: =($A11/AB$5)/365 -> 16.438356
A12: =RAW!$A$10 -> 12400 | C12: Tier V | D12: =($A12/D$5)/365 -> 33.972603 | F12: Tier V | G12: =($A12/G$5)/365 -> 3.7747336 | H12: =($A12/H$5)/365 -> 8.4931507 | I12: =($A12/I$5)/365 -> 4.853229 | J12: =($A12/J$5)/365 -> 6.7945205 | K12: =($A12/K$5)/365 -> 5.6621005 | L12: =($A12/L$5)/365 -> 33.972603 | M12: =($A12/M$5)/365 -> 33.972603 | N12: =($A12/N$5)/365 -> 33.972603 | ... AB12: =($A12/AB$5)/365 -> 33.972603
A13: =RAW!$A$11 -> 25200 | C13: Tier VI | D13: =($A13/D$5)/365 -> 69.041096 | F13: Tier VI | G13: =($A13/G$5)/365 -> 7.6712329 | H13: =($A13/H$5)/365 -> 17.260274 | I13: =($A13/I$5)/365 -> 9.8630137 | J13: =($A13/J$5)/365 -> 13.808219 | K13: =($A13/K$5)/365 -> 11.506849 | L13: =($A13/L$5)/365 -> 69.041096 | M13: =($A13/M$5)/365 -> 69.041096 | N13: =($A13/N$5)/365 -> 69.041096 | ... AB13: =($A13/AB$5)/365 -> 69.041096
A14: =RAW!$A$12 -> 50800 | C14: Tier VII | D14: =($A14/D$5)/365 -> 139.17808 | F14: Tier VII | G14: =($A14/G$5)/365 -> 15.464231 | H14: =($A14/H$5)/365 -> 34.794521 | I14: =($A14/I$5)/365 -> 19.882583 | J14: =($A14/J$5)/365 -> 27.835616 | K14: =($A14/K$5)/365 -> 23.196347 | L14: =($A14/L$5)/365 -> 139.17808 | M14: =($A14/M$5)/365 -> 139.17808 | N14: =($A14/N$5)/365 -> 139.17808 | ... AB14: =($A14/AB$5)/365 -> 139.17808
A15: =RAW!$A$13 -> 102000 | C15: Tier VIII | D15: =($A15/D$5)/365 -> 279.45205 | F15: Tier VIII | G15: =($A15/G$5)/365 -> 31.050228 | H15: =($A15/H$5)/365 -> 69.863014 | I15: =($A15/I$5)/365 -> 39.921722 | J15: =($A15/J$5)/365 -> 55.890411 | K15: =($A15/K$5)/365 -> 46.575342 | L15: =($A15/L$5)/365 -> 279.45205 | M15: =($A15/M$5)/365 -> 279.45205 | N15: =($A15/N$5)/365 -> 279.45205 | ... AB15: =($A15/AB$5)/365 -> 279.45205
A16: =RAW!$A$14 -> 204400 | C16: Tier IX | D16: =($A16/D$5)/365 -> 560 | F16: Tier IX | G16: =($A16/G$5)/365 -> 62.222222 | H16: =($A16/H$5)/365 -> 140 | I16: =($A16/I$5)/365 -> 80 | J16: =($A16/J$5)/365 -> 112 | K16: =($A16/K$5)/365 -> 93.333333 | L16: =($A16/L$5)/365 -> 560 | M16: =($A16/M$5)/365 -> 560 | N16: =($A16/N$5)/365 -> 560 | ... AB16: =($A16/AB$5)/365 -> 560
A17: =RAW!$A$15 -> 409200 | C17: Tier X | D17: =($A17/D$5)/365 -> 1121.0959 | F17: Tier X | G17: =($A17/G$5)/365 -> 124.56621 | H17: =($A17/H$5)/365 -> 280.27397 | I17: =($A17/I$5)/365 -> 160.15656 | J17: =($A17/J$5)/365 -> 224.21918 | K17: =($A17/K$5)/365 -> 186.84932 | L17: =($A17/L$5)/365 -> 1121.0959 | M17: =($A17/M$5)/365 -> 1121.0959 | N17: =($A17/N$5)/365 -> 1121.0959 | ... AB17: =($A17/AB$5)/365 -> 1121.0959
A18: =RAW!$A$16 -> 818800 | C18: Tier XI | D18: =($A18/D$5)/365 -> 2243.2877 | F18: Tier XI | G18: =($A18/G$5)/365 -> 249.25419 | H18: =($A18/H$5)/365 -> 560.82192 | I18: =($A18/I$5)/365 -> 320.46967 | J18: =($A18/J$5)/365 -> 448.65753 | K18: =($A18/K$5)/365 -> 373.88128 | L18: =($A18/L$5)/365 -> 2243.2877 | M18: =($A18/M$5)/365 -> 2243.2877 | N18: =($A18/N$5)/365 -> 2243.2877 | ... AB18: =($A18/AB$5)/365 -> 2243.2877
