Workbook

Sheet Soul Energy Tiers
I1: Casts to upgrade tier | J1: 20 | M1: On a Given Soul Units/Day recharge Rate, how long will it take to reach X Tier? | V1: *Years
A2: Soul Energy Tier | B2: General Power Effects | C2: Power Time (Hours) | D2: RAW Amethyst Cost | E2: RAW Aquamarine Cost | F2: RAW Shappire Cost | G2: Calculated Ball Cost | I2: Soul Cost (Units) | J2: RAW Tier Soul Cost | K2: Accumulative Total Cost | M2: 1 | N2: =1+M2 -> 2 | O2: =1+N2 -> 3 | P2: =1+O2 -> 4 | Q2: =1+P2 -> 5 | R2: =1+Q2 -> 6 | S2: =1+R2 -> 7 | T2: =1+S2 -> 8 | U2: =1+T2 -> 9 | V2: =1+U2 -> 10
A3: Tier I | B3: 0.1 | C3: 1 | D3: 1 | E3: =ROUNDUP(D3/10,0) -> 1 | F3: =ROUNDUP(E3/10,0) -> 1 | G3: 0 S | 0 A | 1 A | I3: 1 | J3: =I3*$J$1 -> 20 | K3: =J3*$J$1 -> 400 | M3: =$K3/M$2 -> 400 | N3: =$K3/N$2 -> 200 | O3: =$K3/O$2 -> 133.33333 | P3: =$K3/P$2 -> 100 | Q3: =$K3/Q$2 -> 80 | R3: =$K3/R$2 -> 66.666667 | S3: =$K3/S$2 -> 57.142857 | T3: =$K3/T$2 -> 50 | ... V3: =$K3/V$2 -> 40
A4: Tier II | B4: =B3*2 -> 0.2 | C4: =C3*2 -> 2 | D4: =D3*2 -> 2 | E4: =ROUNDUP(D4/10,0) -> 1 | F4: =ROUNDUP(E4/10,0) -> 1 | G4: 0 S | 0 A | 2 A | I4: =I3*2 -> 2 | J4: =I4*$J$1 -> 40 | K4: =J4*$J$1+K3 -> 1200 | M4: =$K4/M$2 -> 1200 | N4: =$K4/N$2 -> 600 | O4: =$K4/O$2 -> 400 | P4: =$K4/P$2 -> 300 | Q4: =$K4/Q$2 -> 240 | R4: =$K4/R$2 -> 200 | S4: =$K4/S$2 -> 171.42857 | T4: =$K4/T$2 -> 150 | ... V4: =$K4/V$2 -> 120
A5: Tier III | B5: =B4*2 -> 0.4 | C5: =C4*2 -> 4 | D5: =D4*2 -> 4 | E5: =ROUNDUP(D5/10,0) -> 1 | F5: =ROUNDUP(E5/10,0) -> 1 | G5: 0 S | 0 A | 4 A | I5: =I4*2 -> 4 | J5: =I5*$J$1 -> 80 | K5: =J5*$J$1+K4 -> 2800 | M5: =$K5/M$2 -> 2800 | N5: =$K5/N$2 -> 1400 | O5: =$K5/O$2 -> 933.33333 | P5: =$K5/P$2 -> 700 | Q5: =$K5/Q$2 -> 560 | R5: =$K5/R$2 -> 466.66667 | S5: =$K5/S$2 -> 400 | T5: =$K5/T$2 -> 350 | ... V5: =$K5/V$2 -> 280
A6: Tier IV | B6: =B5*2 -> 0.8 | C6: =C5*2 -> 8 | D6: =D5*2 -> 8 | E6: =ROUNDUP(D6/10,0) -> 1 | F6: =ROUNDUP(E6/10,0) -> 1 | G6: 0 S | 0 A | 8 A | I6: =I5*2 -> 8 | J6: =I6*$J$1 -> 160 | K6: =J6*$J$1+K5 -> 6000 | M6: =$K6/M$2 -> 6000 | N6: =$K6/N$2 -> 3000 | O6: =$K6/O$2 -> 2000 | P6: =$K6/P$2 -> 1500 | Q6: =$K6/Q$2 -> 1200 | R6: =$K6/R$2 -> 1000 | S6: =$K6/S$2 -> 857.14286 | T6: =$K6/T$2 -> 750 | ... V6: =$K6/V$2 -> 600
A7: Tier V | B7: =B6*2 -> 1.6 | C7: =C6*2 -> 16 | D7: =D6*2 -> 16 | E7: =ROUNDUP(D7/10,0) -> 2 | F7: =ROUNDUP(E7/10,0) -> 1 | G7: 0 S | 1 A | 6 A | I7: =I6*2 -> 16 | J7: =I7*$J$1 -> 320 | K7: =J7*$J$1+K6 -> 12400 | M7: =$K7/M$2 -> 12400 | N7: =$K7/N$2 -> 6200 | O7: =$K7/O$2 -> 4133.3333 | P7: =$K7/P$2 -> 3100 | Q7: =$K7/Q$2 -> 2480 | R7: =$K7/R$2 -> 2066.6667 | S7: =$K7/S$2 -> 1771.4286 | T7: =$K7/T$2 -> 1550 | ... V7: =$K7/V$2 -> 1240
A8: Tier VI | B8: =B7*2 -> 3.2 | C8: =C7*2 -> 32 | D8: =D7*2 -> 32 | E8: =ROUNDUP(D8/10,0) -> 4 | F8: =ROUNDUP(E8/10,0) -> 1 | G8: 0 S | 3 A | 2 A | I8: =I7*2 -> 32 | J8: =I8*$J$1 -> 640 | K8: =J8*$J$1+K7 -> 25200 | M8: =($K8/M$2)/365 -> 69.041096 | N8: =($K8/N$2)/365 -> 34.520548 | O8: =($K8/O$2)/365 -> 23.013699 | P8: =($K8/P$2)/365 -> 17.260274 | Q8: =($K8/Q$2)/365 -> 13.808219 | R8: =($K8/R$2)/365 -> 11.506849 | S8: =($K8/S$2)/365 -> 9.8630137 | T8: =($K8/T$2)/365 -> 8.630137 | ... V8: =($K8/V$2)/365 -> 6.9041096
A9: Tier VII | B9: =B8*2 -> 6.4 | C9: =C8*2 -> 64 | D9: =D8*2 -> 64 | E9: =ROUNDUP(D9/10,0) -> 7 | F9: =ROUNDUP(E9/10,0) -> 1 | G9: 0 S | 6 A | 4 A | I9: =I8*2 -> 64 | J9: =I9*$J$1 -> 1280 | K9: =J9*$J$1+K8 -> 50800 | M9: =($K9/M$2)/365 -> 139.17808 | N9: =($K9/N$2)/365 -> 69.589041 | O9: =($K9/O$2)/365 -> 46.392694 | P9: =($K9/P$2)/365 -> 34.794521 | Q9: =($K9/Q$2)/365 -> 27.835616 | R9: =($K9/R$2)/365 -> 23.196347 | S9: =($K9/S$2)/365 -> 19.882583 | T9: =($K9/T$2)/365 -> 17.39726 | ... V9: =($K9/V$2)/365 -> 13.917808
A10: Tier VIII | B10: =B9*2 -> 12.8 | C10: =C9*2 -> 128 | D10: =D9*2 -> 128 | E10: =ROUNDUP(D10/10,0) -> 13 | F10: =ROUNDUP(E10/10,0) -> 2 | G10: 1 S | 2 A | 8 A | I10: =I9*2 -> 128 | J10: =I10*$J$1 -> 2560 | K10: =J10*$J$1+K9 -> 102000 | M10: =($K10/M$2)/365 -> 279.45205 | N10: =($K10/N$2)/365 -> 139.72603 | O10: =($K10/O$2)/365 -> 93.150685 | P10: =($K10/P$2)/365 -> 69.863014 | Q10: =($K10/Q$2)/365 -> 55.890411 | R10: =($K10/R$2)/365 -> 46.575342 | S10: =($K10/S$2)/365 -> 39.921722 | T10: =($K10/T$2)/365 -> 34.931507 | ... V10: =($K10/V$2)/365 -> 27.945205
A11: Tier IX | B11: =B10*2 -> 25.6 | C11: =C10*2 -> 256 | D11: =D10*2 -> 256 | E11: =ROUNDUP(D11/10,0) -> 26 | F11: =ROUNDUP(E11/10,0) -> 3 | G11: 2 S | 5 A | 6 A | I11: =I10*2 -> 256 | J11: =I11*$J$1 -> 5120 | K11: =J11*$J$1+K10 -> 204400 | M11: =($K11/M$2)/365 -> 560 | N11: =($K11/N$2)/365 -> 280 | O11: =($K11/O$2)/365 -> 186.66667 | P11: =($K11/P$2)/365 -> 140 | Q11: =($K11/Q$2)/365 -> 112 | R11: =($K11/R$2)/365 -> 93.333333 | S11: =($K11/S$2)/365 -> 80 | T11: =($K11/T$2)/365 -> 70 | ... V11: =($K11/V$2)/365 -> 56
A12: Tier X | B12: =B11*2 -> 51.2 | C12: =C11*2 -> 512 | D12: =D11*2 -> 512 | E12: =ROUNDUP(D12/10,0) -> 52 | F12: =ROUNDUP(E12/10,0) -> 6 | G12: 5 S | 1 A | 2 A | I12: =I11*2 -> 512 | J12: =I12*$J$1 -> 10240 | K12: =J12*$J$1+K11 -> 409200 | M12: =($K12/M$2)/365 -> 1121.0959 | N12: =($K12/N$2)/365 -> 560.54795 | O12: =($K12/O$2)/365 -> 373.69863 | P12: =($K12/P$2)/365 -> 280.27397 | Q12: =($K12/Q$2)/365 -> 224.21918 | R12: =($K12/R$2)/365 -> 186.84932 | S12: =($K12/S$2)/365 -> 160.15656 | T12: =($K12/T$2)/365 -> 140.13699 | ... V12: =($K12/V$2)/365 -> 112.10959
A13: Tier XI | B13: =B12*2 -> 102.4 | C13: =C12*2 -> 1024 | D13: =D12*2 -> 1024 | E13: =ROUNDUP(D13/10,0) -> 103 | F13: =ROUNDUP(E13/10,0) -> 11 | G13: 10 S | 2 A | 4 A | I13: =I12*2 -> 1024 | J13: =I13*$J$1 -> 20480 | K13: =J13*$J$1+K12 -> 818800 | M13: =($K13/M$2)/365 -> 2243.2877 | N13: =($K13/N$2)/365 -> 1121.6438 | O13: =($K13/O$2)/365 -> 747.76256 | P13: =($K13/P$2)/365 -> 560.82192 | Q13: =($K13/Q$2)/365 -> 448.65753 | R13: =($K13/R$2)/365 -> 373.88128 | S13: =($K13/S$2)/365 -> 320.46967 | T13: =($K13/T$2)/365 -> 280.41096 | ... V13: =($K13/V$2)/365 -> 224.32877
A14: Tier XII | B14: =B13*2 -> 204.8 | C14: =C13*2 -> 2048 | D14: =D13*2 -> 2048 | E14: =ROUNDUP(D14/10,0) -> 205 | F14: =ROUNDUP(E14/10,0) -> 21 | G14: 20 S | 4 A | 8 A | I14: =I13*2 -> 2048 | J14: =I14*$J$1 -> 40960 | K14: =J14*$J$1+K13 -> 1638000 | M14: =($K14/M$2)/365 -> 4487.6712 | N14: =($K14/N$2)/365 -> 2243.8356 | O14: =($K14/O$2)/365 -> 1495.8904 | P14: =($K14/P$2)/365 -> 1121.9178 | Q14: =($K14/Q$2)/365 -> 897.53425 | R14: =($K14/R$2)/365 -> 747.94521 | S14: =($K14/S$2)/365 -> 641.09589 | T14: =($K14/T$2)/365 -> 560.9589 | ... V14: =($K14/V$2)/365 -> 448.76712
A15: Tier XIII | B15: =B14*2 -> 409.6 | C15: =C14*2 -> 4096 | D15: =D14*2 -> 4096 | E15: =ROUNDUP(D15/10,0) -> 410 | F15: =ROUNDUP(E15/10,0) -> 41 | G15: 40 S | 9 A | 6 A | I15: =I14*2 -> 4096 | J15: =I15*$J$1 -> 81920 | K15: =J15*$J$1+K14 -> 3276400 | M15: =($K15/M$2)/365 -> 8976.4384 | N15: =($K15/N$2)/365 -> 4488.2192 | O15: =($K15/O$2)/365 -> 2992.1461 | P15: =($K15/P$2)/365 -> 2244.1096 | Q15: =($K15/Q$2)/365 -> 1795.2877 | R15: =($K15/R$2)/365 -> 1496.0731 | S15: =($K15/S$2)/365 -> 1282.3483 | T15: =($K15/T$2)/365 -> 1122.0548 | ... V15: =($K15/V$2)/365 -> 897.64384
A16: Tier XIV | B16: =B15*2 -> 819.2 | C16: =C15*2 -> 8192 | D16: =D15*2 -> 8192 | E16: =ROUNDUP(D16/10,0) -> 820 | F16: =ROUNDUP(E16/10,0) -> 82 | G16: 81 S | 9 A | 2 A | I16: =I15*2 -> 8192 | J16: =I16*$J$1 -> 163840 | K16: =J16*$J$1+K15 -> 6553200 | M16: =($K16/M$2)/365 -> 17953.973 | N16: =($K16/N$2)/365 -> 8976.9863 | O16: =($K16/O$2)/365 -> 5984.6575 | P16: =($K16/P$2)/365 -> 4488.4932 | Q16: =($K16/Q$2)/365 -> 3590.7945 | R16: =($K16/R$2)/365 -> 2992.3288 | S16: =($K16/S$2)/365 -> 2564.8532 | T16: =($K16/T$2)/365 -> 2244.2466 | ... V16: =($K16/V$2)/365 -> 1795.3973
A17: Tier XV | B17: =B16*2 -> 1638.4 | C17: =C16*2 -> 16384 | D17: =D16*2 -> 16384 | E17: =ROUNDUP(D17/10,0) -> 1639 | F17: =ROUNDUP(E17/10,0) -> 164 | G17: 163 S | 8 A | 4 A | I17: =I16*2 -> 16384 | J17: =I17*$J$1 -> 327680 | K17: =J17*$J$1+K16 -> 13106800 | M17: =($K17/M$2)/365 -> 35909.041 | N17: =($K17/N$2)/365 -> 17954.521 | O17: =($K17/O$2)/365 -> 11969.68 | P17: =($K17/P$2)/365 -> 8977.2603 | Q17: =($K17/Q$2)/365 -> 7181.8082 | R17: =($K17/R$2)/365 -> 5984.8402 | S17: =($K17/S$2)/365 -> 5129.863 | T17: =($K17/T$2)/365 -> 4488.6301 | ... V17: =($K17/V$2)/365 -> 3590.9041
A18: Tier XVI | B18: =B17*2 -> 3276.8 | C18: =C17*2 -> 32768 | D18: =D17*2 -> 32768 | E18: =ROUNDUP(D18/10,0) -> 3277 | F18: =ROUNDUP(E18/10,0) -> 328 | G18: 327 S | 6 A | 8 A | I18: =I17*2 -> 32768 | J18: =I18*$J$1 -> 655360 | K18: =J18*$J$1+K17 -> 26214000 | M18: =($K18/M$2)/365 -> 71819.178 | N18: =($K18/N$2)/365 -> 35909.589 | O18: =($K18/O$2)/365 -> 23939.726 | P18: =($K18/P$2)/365 -> 17954.795 | Q18: =($K18/Q$2)/365 -> 14363.836 | R18: =($K18/R$2)/365 -> 11969.863 | S18: =($K18/S$2)/365 -> 10259.883 | T18: =($K18/T$2)/365 -> 8977.3973 | ... V18: =($K18/V$2)/365 -> 7181.9178
A19: Tier XVII | B19: =B18*2 -> 6553.6 | C19: =C18*2 -> 65536 | D19: =D18*2 -> 65536 | E19: =ROUNDUP(D19/10,0) -> 6554 | F19: =ROUNDUP(E19/10,0) -> 656 | G19: 655 S | 3 A | 6 A | I19: =I18*2 -> 65536 | J19: =I19*$J$1 -> 1310720 | K19: =J19*$J$1+K18 -> 52428400 | M19: =($K19/M$2)/365 -> 143639.45 | N19: =($K19/N$2)/365 -> 71819.726 | O19: =($K19/O$2)/365 -> 47879.817 | P19: =($K19/P$2)/365 -> 35909.863 | Q19: =($K19/Q$2)/365 -> 28727.89 | R19: =($K19/R$2)/365 -> 23939.909 | S19: =($K19/S$2)/365 -> 20519.922 | T19: =($K19/T$2)/365 -> 17954.932 | ... V19: =($K19/V$2)/365 -> 14363.945

Sheet Race Soul Avg + Char Calculator
C1: CHAR CALC | G1: FAUNA (HERBIVORES) AVERAGE
A2: Below Child years is equals to shares of parents soul being infused | C2: Child | D2: =D3/12 -> 2.2727273 | F2: Child | G2: =G3/12 -> 13.257576 | H2: =H3/12 -> 17.045455 | J2: =J3/12 -> 1.8939394 | K2: =K3/12 -> 3.7878788 | M2: =M3/12 -> 7.5757576 | N2: =N3/12 -> 9.469697 | P2: =P3/12 -> 18.939394 | Q2: =Q3/12 -> 37.878788 | S2: =S3/12 -> 3.7878788 | T2: =T3/12 -> 6.6287879 | V2: =V3/12 -> 0.9469697 | W2: =W3/12 -> 2.8409091 | Y2: =Y3/12 -> 0.56818182 | Z2: =Z3/12 -> 1.1363636 | AB2: =AB3/12 -> 1.3257576 | AC2: =AC3/12 -> 2.6515152 | AE2: =AE3/12 -> 0.9469697 | AF2: =AF3/12 -> 0.9469697 | AH2: =AH3/12 -> 0.018939394 | AI2: =AI3/12 -> 0.018939394 | AK2: =AK3/12 -> 0.018939394 | AL2: =AL3/12 -> 0.018939394
C3: Adulthood | D3: =D4/4.4 -> 27.272727 | F3: Adulthood | G3: =G4/4.4 -> 159.09091 | H3: =H4/4.4 -> 204.54545 | J3: =J4/4.4 -> 22.727273 | K3: =K4/4.4 -> 45.454545 | M3: =M4/4.4 -> 90.909091 | N3: =N4/4.4 -> 113.63636 | P3: =P4/4.4 -> 227.27273 | Q3: =Q4/4.4 -> 454.54545 | S3: =S4/4.4 -> 45.454545 | T3: =T4/4.4 -> 79.545455 | V3: =V4/4.4 -> 11.363636 | W3: =W4/4.4 -> 34.090909 | Y3: =Y4/4.4 -> 6.8181818 | Z3: =Z4/4.4 -> 13.636364 | AB3: =AB4/4.4 -> 15.909091 | AC3: =AC4/4.4 -> 31.818182 | AE3: =AE4/4.4 -> 11.363636 | AF3: =AF4/4.4 -> 11.363636 | AH3: =AH4/4.4 -> 0.22727273 | AI3: =AI4/4.4 -> 0.22727273 | AK3: =AK4/4.4 -> 0.22727273 | AL3: =AL4/4.4 -> 0.22727273
C4: Lifespan | D4: 120 | F4: Lifespan | G4: 700 | H4: 900 | J4: 100 | K4: 200 | M4: 400 | N4: 500 | P4: 1000 | Q4: 2000 | S4: 200 | T4: 350 | V4: 50 | W4: 150 | Y4: 30 | Z4: 60 | AB4: 70 | AC4: 140 | AE4: 50 | AF4: 50 | AH4: 1 | AI4: 1 | AK4: 1 | AL4: 1
C5: Soul Recharge/Day | D5: 139 | F5: Soul Recharge/Day | G5: 30 | H5: 60 | J5: 1 | K5: 5 | M5: 4 | N5: 8 | P5: 30 | Q5: 60 | S5: 5 | T5: 15 | V5: 10 | W5: 25 | Y5: 250 | Z5: 150 | AB5: 3 | AC5: 40 | AE5: 1 | AF5: 10 | AH5: 1 | AI5: 1 | AK5: 1 | AL5: 1
G6: Average Total Years to Reach Tier
A7: Accumulative Total Cost | C7: Soul Energy Tier | D7: Char | F7: Soul Energy Tier | G7: Finaies (Low) | H7: Finaies (High) | J7: Lishies (Low) | K7: Lishies (High) | M7: Buhraies (Low) | N7: Buhraies (High) | P7: Fuhraies (Low) | Q7: Fuhraies (High) | S7: Darfaries (Low) | T7: Darfaries (High) | V7: Wozefaries (Low) | W7: Wozefaries (High) | Y7: Sorefaries (Low) | Z7: Sorefaries (High) | AB7: Humans (Low) | AC7: Humans (High) | AE7: Cruros (Low) | AF7: Cruros (High)
A8: ='Soul Energy Tiers'!K3 -> 400 | C8: Tier I | D8: =($A8/D$5)/365 -> 0.0078841037 | F8: Tier I | G8: =($A8/G$5)/365 -> 0.03652968 | H8: =($A8/H$5)/365 -> 0.01826484 | J8: =($A8/J$5)/365 -> 1.0958904 | K8: =($A8/K$5)/365 -> 0.21917808 | M8: =($A8/M$5)/365 -> 0.2739726 | N8: =($A8/N$5)/365 -> 0.1369863 | P8: =($A8/P$5)/365 -> 0.03652968 | Q8: =($A8/Q$5)/365 -> 0.01826484 | S8: =($A8/S$5)/365 -> 0.21917808 | T8: =($A8/T$5)/365 -> 0.073059361 | V8: =($A8/V$5)/365 -> 0.10958904 | W8: =($A8/W$5)/365 -> 0.043835616 | Y8: =($A8/Y$5)/365 -> 0.0043835616 | Z8: =($A8/Z$5)/365 -> 0.0073059361 | AB8: =($A8/AB$5)/365 -> 0.3652968 | AC8: =($A8/AC$5)/365 -> 0.02739726 | AE8: =($A8/AE$5)/365 -> 1.0958904 | AF8: =($A8/AF$5)/365 -> 0.10958904 | AH8: =($A8/AH$5)/365 -> 1.0958904 | AI8: =($A8/AI$5)/365 -> 1.0958904 | AK8: =($A8/AK$5)/365 -> 1.0958904 | AL8: =($A8/AL$5)/365 -> 1.0958904
A9: ='Soul Energy Tiers'!K4 -> 1200 | C9: Tier II | D9: =($A9/D$5)/365 -> 0.023652311 | F9: Tier II | G9: =($A9/G$5)/365 -> 0.10958904 | H9: =($A9/H$5)/365 -> 0.054794521 | J9: =($A9/J$5)/365 -> 3.2876712 | K9: =($A9/K$5)/365 -> 0.65753425 | M9: =($A9/M$5)/365 -> 0.82191781 | N9: =($A9/N$5)/365 -> 0.4109589 | P9: =($A9/P$5)/365 -> 0.10958904 | Q9: =($A9/Q$5)/365 -> 0.054794521 | S9: =($A9/S$5)/365 -> 0.65753425 | T9: =($A9/T$5)/365 -> 0.21917808 | V9: =($A9/V$5)/365 -> 0.32876712 | W9: =($A9/W$5)/365 -> 0.13150685 | Y9: =($A9/Y$5)/365 -> 0.013150685 | Z9: =($A9/Z$5)/365 -> 0.021917808 | AB9: =($A9/AB$5)/365 -> 1.0958904 | AC9: =($A9/AC$5)/365 -> 0.082191781 | AE9: =($A9/AE$5)/365 -> 3.2876712 | AF9: =($A9/AF$5)/365 -> 0.32876712 | AH9: =($A9/AH$5)/365 -> 3.2876712 | AI9: =($A9/AI$5)/365 -> 3.2876712 | AK9: =($A9/AK$5)/365 -> 3.2876712 | AL9: =($A9/AL$5)/365 -> 3.2876712
A10: ='Soul Energy Tiers'!K5 -> 2800 | C10: Tier III | D10: =($A10/D$5)/365 -> 0.055188726 | F10: Tier III | G10: =($A10/G$5)/365 -> 0.25570776 | H10: =($A10/H$5)/365 -> 0.12785388 | J10: =($A10/J$5)/365 -> 7.6712329 | K10: =($A10/K$5)/365 -> 1.5342466 | M10: =($A10/M$5)/365 -> 1.9178082 | N10: =($A10/N$5)/365 -> 0.95890411 | P10: =($A10/P$5)/365 -> 0.25570776 | Q10: =($A10/Q$5)/365 -> 0.12785388 | S10: =($A10/S$5)/365 -> 1.5342466 | T10: =($A10/T$5)/365 -> 0.51141553 | V10: =($A10/V$5)/365 -> 0.76712329 | W10: =($A10/W$5)/365 -> 0.30684932 | Y10: =($A10/Y$5)/365 -> 0.030684932 | Z10: =($A10/Z$5)/365 -> 0.051141553 | AB10: =($A10/AB$5)/365 -> 2.5570776 | AC10: =($A10/AC$5)/365 -> 0.19178082 | AE10: =($A10/AE$5)/365 -> 7.6712329 | AF10: =($A10/AF$5)/365 -> 0.76712329 | AH10: =($A10/AH$5)/365 -> 7.6712329 | AI10: =($A10/AI$5)/365 -> 7.6712329 | AK10: =($A10/AK$5)/365 -> 7.6712329 | AL10: =($A10/AL$5)/365 -> 7.6712329
A11: ='Soul Energy Tiers'!K6 -> 6000 | C11: Tier IV | D11: =($A11/D$5)/365 -> 0.11826156 | F11: Tier IV | G11: =($A11/G$5)/365 -> 0.54794521 | H11: =($A11/H$5)/365 -> 0.2739726 | J11: =($A11/J$5)/365 -> 16.438356 | K11: =($A11/K$5)/365 -> 3.2876712 | M11: =($A11/M$5)/365 -> 4.109589 | N11: =($A11/N$5)/365 -> 2.0547945 | P11: =($A11/P$5)/365 -> 0.54794521 | Q11: =($A11/Q$5)/365 -> 0.2739726 | S11: =($A11/S$5)/365 -> 3.2876712 | T11: =($A11/T$5)/365 -> 1.0958904 | V11: =($A11/V$5)/365 -> 1.6438356 | W11: =($A11/W$5)/365 -> 0.65753425 | Y11: =($A11/Y$5)/365 -> 0.065753425 | Z11: =($A11/Z$5)/365 -> 0.10958904 | AB11: =($A11/AB$5)/365 -> 5.4794521 | AC11: =($A11/AC$5)/365 -> 0.4109589 | AE11: =($A11/AE$5)/365 -> 16.438356 | AF11: =($A11/AF$5)/365 -> 1.6438356 | AH11: =($A11/AH$5)/365 -> 16.438356 | AI11: =($A11/AI$5)/365 -> 16.438356 | AK11: =($A11/AK$5)/365 -> 16.438356 | AL11: =($A11/AL$5)/365 -> 16.438356
A12: ='Soul Energy Tiers'!K7 -> 12400 | C12: Tier V | D12: =($A12/D$5)/365 -> 0.24440721 | F12: Tier V | G12: =($A12/G$5)/365 -> 1.1324201 | H12: =($A12/H$5)/365 -> 0.56621005 | J12: =($A12/J$5)/365 -> 33.972603 | K12: =($A12/K$5)/365 -> 6.7945205 | M12: =($A12/M$5)/365 -> 8.4931507 | N12: =($A12/N$5)/365 -> 4.2465753 | P12: =($A12/P$5)/365 -> 1.1324201 | Q12: =($A12/Q$5)/365 -> 0.56621005 | S12: =($A12/S$5)/365 -> 6.7945205 | T12: =($A12/T$5)/365 -> 2.2648402 | V12: =($A12/V$5)/365 -> 3.3972603 | W12: =($A12/W$5)/365 -> 1.3589041 | Y12: =($A12/Y$5)/365 -> 0.13589041 | Z12: =($A12/Z$5)/365 -> 0.22648402 | AB12: =($A12/AB$5)/365 -> 11.324201 | AC12: =($A12/AC$5)/365 -> 0.84931507 | AE12: =($A12/AE$5)/365 -> 33.972603 | AF12: =($A12/AF$5)/365 -> 3.3972603 | AH12: =($A12/AH$5)/365 -> 33.972603 | AI12: =($A12/AI$5)/365 -> 33.972603 | AK12: =($A12/AK$5)/365 -> 33.972603 | AL12: =($A12/AL$5)/365 -> 33.972603
A13: ='Soul Energy Tiers'!K8 -> 25200 | C13: Tier VI | D13: =($A13/D$5)/365 -> 0.49669853 | F13: Tier VI | G13: =($A13/G$5)/365 -> 2.3013699 | H13: =($A13/H$5)/365 -> 1.1506849 | J13: =($A13/J$5)/365 -> 69.041096 | K13: =($A13/K$5)/365 -> 13.808219 | M13: =($A13/M$5)/365 -> 17.260274 | N13: =($A13/N$5)/365 -> 8.630137 | P13: =($A13/P$5)/365 -> 2.3013699 | Q13: =($A13/Q$5)/365 -> 1.1506849 | S13: =($A13/S$5)/365 -> 13.808219 | T13: =($A13/T$5)/365 -> 4.6027397 | V13: =($A13/V$5)/365 -> 6.9041096 | W13: =($A13/W$5)/365 -> 2.7616438 | Y13: =($A13/Y$5)/365 -> 0.27616438 | Z13: =($A13/Z$5)/365 -> 0.46027397 | AB13: =($A13/AB$5)/365 -> 23.013699 | AC13: =($A13/AC$5)/365 -> 1.7260274 | AE13: =($A13/AE$5)/365 -> 69.041096 | AF13: =($A13/AF$5)/365 -> 6.9041096 | AH13: =($A13/AH$5)/365 -> 69.041096 | AI13: =($A13/AI$5)/365 -> 69.041096 | AK13: =($A13/AK$5)/365 -> 69.041096 | AL13: =($A13/AL$5)/365 -> 69.041096
A14: ='Soul Energy Tiers'!K9 -> 50800 | C14: Tier VII | D14: =($A14/D$5)/365 -> 1.0012812 | F14: Tier VII | G14: =($A14/G$5)/365 -> 4.6392694 | H14: =($A14/H$5)/365 -> 2.3196347 | J14: =($A14/J$5)/365 -> 139.17808 | K14: =($A14/K$5)/365 -> 27.835616 | M14: =($A14/M$5)/365 -> 34.794521 | N14: =($A14/N$5)/365 -> 17.39726 | P14: =($A14/P$5)/365 -> 4.6392694 | Q14: =($A14/Q$5)/365 -> 2.3196347 | S14: =($A14/S$5)/365 -> 27.835616 | T14: =($A14/T$5)/365 -> 9.2785388 | V14: =($A14/V$5)/365 -> 13.917808 | W14: =($A14/W$5)/365 -> 5.5671233 | Y14: =($A14/Y$5)/365 -> 0.55671233 | Z14: =($A14/Z$5)/365 -> 0.92785388 | AB14: =($A14/AB$5)/365 -> 46.392694 | AC14: =($A14/AC$5)/365 -> 3.4794521 | AE14: =($A14/AE$5)/365 -> 139.17808 | AF14: =($A14/AF$5)/365 -> 13.917808 | AH14: =($A14/AH$5)/365 -> 139.17808 | AI14: =($A14/AI$5)/365 -> 139.17808 | AK14: =($A14/AK$5)/365 -> 139.17808 | AL14: =($A14/AL$5)/365 -> 139.17808
A15: ='Soul Energy Tiers'!K10 -> 102000 | C15: Tier VIII | D15: =($A15/D$5)/365 -> 2.0104464 | F15: Tier VIII | G15: =($A15/G$5)/365 -> 9.3150685 | H15: =($A15/H$5)/365 -> 4.6575342 | J15: =($A15/J$5)/365 -> 279.45205 | K15: =($A15/K$5)/365 -> 55.890411 | M15: =($A15/M$5)/365 -> 69.863014 | N15: =($A15/N$5)/365 -> 34.931507 | P15: =($A15/P$5)/365 -> 9.3150685 | Q15: =($A15/Q$5)/365 -> 4.6575342 | S15: =($A15/S$5)/365 -> 55.890411 | T15: =($A15/T$5)/365 -> 18.630137 | V15: =($A15/V$5)/365 -> 27.945205 | W15: =($A15/W$5)/365 -> 11.178082 | Y15: =($A15/Y$5)/365 -> 1.1178082 | Z15: =($A15/Z$5)/365 -> 1.8630137 | AB15: =($A15/AB$5)/365 -> 93.150685 | AC15: =($A15/AC$5)/365 -> 6.9863014 | AE15: =($A15/AE$5)/365 -> 279.45205 | AF15: =($A15/AF$5)/365 -> 27.945205 | AH15: =($A15/AH$5)/365 -> 279.45205 | AI15: =($A15/AI$5)/365 -> 279.45205 | AK15: =($A15/AK$5)/365 -> 279.45205 | AL15: =($A15/AL$5)/365 -> 279.45205
A16: ='Soul Energy Tiers'!K11 -> 204400 | C16: Tier IX | D16: =($A16/D$5)/365 -> 4.028777 | F16: Tier IX | G16: =($A16/G$5)/365 -> 18.666667 | H16: =($A16/H$5)/365 -> 9.3333333 | J16: =($A16/J$5)/365 -> 560 | K16: =($A16/K$5)/365 -> 112 | M16: =($A16/M$5)/365 -> 140 | N16: =($A16/N$5)/365 -> 70 | P16: =($A16/P$5)/365 -> 18.666667 | Q16: =($A16/Q$5)/365 -> 9.3333333 | S16: =($A16/S$5)/365 -> 112 | T16: =($A16/T$5)/365 -> 37.333333 | V16: =($A16/V$5)/365 -> 56 | W16: =($A16/W$5)/365 -> 22.4 | Y16: =($A16/Y$5)/365 -> 2.24 | Z16: =($A16/Z$5)/365 -> 3.7333333 | AB16: =($A16/AB$5)/365 -> 186.66667 | AC16: =($A16/AC$5)/365 -> 14 | AE16: =($A16/AE$5)/365 -> 560 | AF16: =($A16/AF$5)/365 -> 56 | AH16: =($A16/AH$5)/365 -> 560 | AI16: =($A16/AI$5)/365 -> 560 | AK16: =($A16/AK$5)/365 -> 560 | AL16: =($A16/AL$5)/365 -> 560
A17: ='Soul Energy Tiers'!K12 -> 409200 | C17: Tier X | D17: =($A17/D$5)/365 -> 8.0654381 | F17: Tier X | G17: =($A17/G$5)/365 -> 37.369863 | H17: =($A17/H$5)/365 -> 18.684932 | J17: =($A17/J$5)/365 -> 1121.0959 | K17: =($A17/K$5)/365 -> 224.21918 | M17: =($A17/M$5)/365 -> 280.27397 | N17: =($A17/N$5)/365 -> 140.13699 | P17: =($A17/P$5)/365 -> 37.369863 | Q17: =($A17/Q$5)/365 -> 18.684932 | S17: =($A17/S$5)/365 -> 224.21918 | T17: =($A17/T$5)/365 -> 74.739726 | V17: =($A17/V$5)/365 -> 112.10959 | W17: =($A17/W$5)/365 -> 44.843836 | Y17: =($A17/Y$5)/365 -> 4.4843836 | Z17: =($A17/Z$5)/365 -> 7.4739726 | AB17: =($A17/AB$5)/365 -> 373.69863 | AC17: =($A17/AC$5)/365 -> 28.027397 | AE17: =($A17/AE$5)/365 -> 1121.0959 | AF17: =($A17/AF$5)/365 -> 112.10959 | AH17: =($A17/AH$5)/365 -> 1121.0959 | AI17: =($A17/AI$5)/365 -> 1121.0959 | AK17: =($A17/AK$5)/365 -> 1121.0959 | AL17: =($A17/AL$5)/365 -> 1121.0959
A18: ='Soul Energy Tiers'!K13 -> 818800 | C18: Tier XI | D18: =($A18/D$5)/365 -> 16.13876 | F18: Tier XI | G18: =($A18/G$5)/365 -> 74.776256 | H18: =($A18/H$5)/365 -> 37.388128 | J18: =($A18/J$5)/365 -> 2243.2877 | K18: =($A18/K$5)/365 -> 448.65753 | M18: =($A18/M$5)/365 -> 560.82192 | N18: =($A18/N$5)/365 -> 280.41096 | P18: =($A18/P$5)/365 -> 74.776256 | Q18: =($A18/Q$5)/365 -> 37.388128 | S18: =($A18/S$5)/365 -> 448.65753 | T18: =($A18/T$5)/365 -> 149.55251 | V18: =($A18/V$5)/365 -> 224.32877 | W18: =($A18/W$5)/365 -> 89.731507 | Y18: =($A18/Y$5)/365 -> 8.9731507 | Z18: =($A18/Z$5)/365 -> 14.955251 | AB18: =($A18/AB$5)/365 -> 747.76256 | AC18: =($A18/AC$5)/365 -> 56.082192 | AE18: =($A18/AE$5)/365 -> 2243.2877 | AF18: =($A18/AF$5)/365 -> 224.32877 | AH18: =($A18/AH$5)/365 -> 2243.2877 | AI18: =($A18/AI$5)/365 -> 2243.2877 | AK18: =($A18/AK$5)/365 -> 2243.2877 | AL18: =($A18/AL$5)/365 -> 2243.2877
A19: ='Soul Energy Tiers'!K14 -> 1638000 | C19: Tier XII | D19: =($A19/D$5)/365 -> 32.285405 | F19: Tier XII | G19: =($A19/G$5)/365 -> 149.58904 | H19: =($A19/H$5)/365 -> 74.794521 | J19: =($A19/J$5)/365 -> 4487.6712 | K19: =($A19/K$5)/365 -> 897.53425 | M19: =($A19/M$5)/365 -> 1121.9178 | N19: =($A19/N$5)/365 -> 560.9589 | P19: =($A19/P$5)/365 -> 149.58904 | Q19: =($A19/Q$5)/365 -> 74.794521 | S19: =($A19/S$5)/365 -> 897.53425 | T19: =($A19/T$5)/365 -> 299.17808 | V19: =($A19/V$5)/365 -> 448.76712 | W19: =($A19/W$5)/365 -> 179.50685 | Y19: =($A19/Y$5)/365 -> 17.950685 | Z19: =($A19/Z$5)/365 -> 29.917808 | AB19: =($A19/AB$5)/365 -> 1495.8904 | AC19: =($A19/AC$5)/365 -> 112.19178 | AE19: =($A19/AE$5)/365 -> 4487.6712 | AF19: =($A19/AF$5)/365 -> 448.76712 | AH19: =($A19/AH$5)/365 -> 4487.6712 | AI19: =($A19/AI$5)/365 -> 4487.6712 | AK19: =($A19/AK$5)/365 -> 4487.6712 | AL19: =($A19/AL$5)/365 -> 4487.6712
... A24: ='Soul Energy Tiers'!K19 -> 52428400 | C24: Tier XVII | D24: =($A24/D$5)/365 -> 1033.3774 | F24: Tier XVII | G24: =($A24/G$5)/365 -> 4787.9817 | H24: =($A24/H$5)/365 -> 2393.9909 | J24: =($A24/J$5)/365 -> 143639.45 | K24: =($A24/K$5)/365 -> 28727.89 | M24: =($A24/M$5)/365 -> 35909.863 | N24: =($A24/N$5)/365 -> 17954.932 | P24: =($A24/P$5)/365 -> 4787.9817 | Q24: =($A24/Q$5)/365 -> 2393.9909 | S24: =($A24/S$5)/365 -> 28727.89 | T24: =($A24/T$5)/365 -> 9575.9635 | V24: =($A24/V$5)/365 -> 14363.945 | W24: =($A24/W$5)/365 -> 5745.5781 | Y24: =($A24/Y$5)/365 -> 574.55781 | Z24: =($A24/Z$5)/365 -> 957.59635 | AB24: =($A24/AB$5)/365 -> 47879.817 | AC24: =($A24/AC$5)/365 -> 3590.9863 | AE24: =($A24/AE$5)/365 -> 143639.45 | AF24: =($A24/AF$5)/365 -> 14363.945 | AH24: =($A24/AH$5)/365 -> 143639.45 | AI24: =($A24/AI$5)/365 -> 143639.45 | AK24: =($A24/AK$5)/365 -> 143639.45 | AL24: =($A24/AL$5)/365 -> 143639.45
G25: How Many days does it take to recharge a spell
A26: Spell Soul Cost | C26: Soul Energy Tier | D26: Char | F26: Soul Energy Tier | G26: =G7 -> Finaies (Low) | H26: =H7 -> Finaies (High) | J26: =J7 -> Lishies (Low) | K26: =K7 -> Lishies (High) | M26: =M7 -> Buhraies (Low) | N26: =N7 -> Buhraies (High) | P26: =P7 -> Fuhraies (Low) | Q26: =Q7 -> Fuhraies (High) | S26: =S7 -> Darfaries (Low) | T26: =T7 -> Darfaries (High) | V26: =V7 -> Wozefaries (Low) | W26: =W7 -> Wozefaries (High) | Y26: =Y7 -> Sorefaries (Low) | Z26: =Z7 -> Sorefaries (High) | AB26: =AB7 -> Humans (Low) | AC26: =AC7 -> Humans (High) | AE26: =AE7 -> Cruros (Low) | AF26: =AF7 -> Cruros (High) | AH26: =AH7 | AI26: =AI7 | AK26: =AK7 | AL26: =AL7
A27: ='Soul Energy Tiers'!J3 -> 20 | C27: Tier I | D27: =$A27/D$5 -> 0.14388489 | F27: Tier I | G27: =$A27/G$5 -> 0.66666667 | H27: =$A27/H$5 -> 0.33333333 | J27: =$A27/J$5 -> 20 | K27: =$A27/K$5 -> 4 | M27: =$A27/M$5 -> 5 | N27: =$A27/N$5 -> 2.5 | P27: =$A27/P$5 -> 0.66666667 | Q27: =$A27/Q$5 -> 0.33333333 | S27: =$A27/S$5 -> 4 | T27: =$A27/T$5 -> 1.3333333 | V27: =$A27/V$5 -> 2 | W27: =$A27/W$5 -> 0.8 | Y27: =$A27/Y$5 -> 0.08 | Z27: =$A27/Z$5 -> 0.13333333 | AB27: =$A27/AB$5 -> 6.6666667 | AC27: =$A27/AC$5 -> 0.5 | AE27: =$A27/AE$5 -> 20 | AF27: =$A27/AF$5 -> 2 | AH27: =$A27/AH$5 -> 20 | AI27: =$A27/AI$5 -> 20 | AK27: =$A27/AK$5 -> 20 | AL27: =$A27/AL$5 -> 20
A28: ='Soul Energy Tiers'!J4 -> 40 | C28: Tier II | D28: =$A28/D$5 -> 0.28776978 | F28: Tier II | G28: =$A28/G$5 -> 1.3333333 | H28: =$A28/H$5 -> 0.66666667 | J28: =$A28/J$5 -> 40 | K28: =$A28/K$5 -> 8 | M28: =$A28/M$5 -> 10 | N28: =$A28/N$5 -> 5 | P28: =$A28/P$5 -> 1.3333333 | Q28: =$A28/Q$5 -> 0.66666667 | S28: =$A28/S$5 -> 8 | T28: =$A28/T$5 -> 2.6666667 | V28: =$A28/V$5 -> 4 | W28: =$A28/W$5 -> 1.6 | Y28: =$A28/Y$5 -> 0.16 | Z28: =$A28/Z$5 -> 0.26666667 | AB28: =$A28/AB$5 -> 13.333333 | AC28: =$A28/AC$5 -> 1 | AE28: =$A28/AE$5 -> 40 | AF28: =$A28/AF$5 -> 4 | AH28: =$A28/AH$5 -> 40 | AI28: =$A28/AI$5 -> 40 | AK28: =$A28/AK$5 -> 40 | AL28: =$A28/AL$5 -> 40
A29: ='Soul Energy Tiers'!J5 -> 80 | C29: Tier III | D29: =$A29/D$5 -> 0.57553957 | F29: Tier III | G29: =$A29/G$5 -> 2.6666667 | H29: =$A29/H$5 -> 1.3333333 | J29: =$A29/J$5 -> 80 | K29: =$A29/K$5 -> 16 | M29: =$A29/M$5 -> 20 | N29: =$A29/N$5 -> 10 | P29: =$A29/P$5 -> 2.6666667 | Q29: =$A29/Q$5 -> 1.3333333 | S29: =$A29/S$5 -> 16 | T29: =$A29/T$5 -> 5.3333333 | V29: =$A29/V$5 -> 8 | W29: =$A29/W$5 -> 3.2 | Y29: =$A29/Y$5 -> 0.32 | Z29: =$A29/Z$5 -> 0.53333333 | AB29: =$A29/AB$5 -> 26.666667 | AC29: =$A29/AC$5 -> 2 | AE29: =$A29/AE$5 -> 80 | AF29: =$A29/AF$5 -> 8 | AH29: =$A29/AH$5 -> 80 | AI29: =$A29/AI$5 -> 80 | AK29: =$A29/AK$5 -> 80 | AL29: =$A29/AL$5 -> 80
A30: ='Soul Energy Tiers'!J6 -> 160 | C30: Tier IV | D30: =$A30/D$5 -> 1.1510791 | F30: Tier IV | G30: =$A30/G$5 -> 5.3333333 | H30: =$A30/H$5 -> 2.6666667 | J30: =$A30/J$5 -> 160 | K30: =$A30/K$5 -> 32 | M30: =$A30/M$5 -> 40 | N30: =$A30/N$5 -> 20 | P30: =$A30/P$5 -> 5.3333333 | Q30: =$A30/Q$5 -> 2.6666667 | S30: =$A30/S$5 -> 32 | T30: =$A30/T$5 -> 10.666667 | V30: =$A30/V$5 -> 16 | W30: =$A30/W$5 -> 6.4 | Y30: =$A30/Y$5 -> 0.64 | Z30: =$A30/Z$5 -> 1.0666667 | AB30: =$A30/AB$5 -> 53.333333 | AC30: =$A30/AC$5 -> 4 | AE30: =$A30/AE$5 -> 160 | AF30: =$A30/AF$5 -> 16 | AH30: =$A30/AH$5 -> 160 | AI30: =$A30/AI$5 -> 160 | AK30: =$A30/AK$5 -> 160 | AL30: =$A30/AL$5 -> 160
A31: ='Soul Energy Tiers'!J7 -> 320 | C31: Tier V | D31: =$A31/D$5 -> 2.3021583 | F31: Tier V | G31: =$A31/G$5 -> 10.666667 | H31: =$A31/H$5 -> 5.3333333 | J31: =$A31/J$5 -> 320 | K31: =$A31/K$5 -> 64 | M31: =$A31/M$5 -> 80 | N31: =$A31/N$5 -> 40 | P31: =$A31/P$5 -> 10.666667 | Q31: =$A31/Q$5 -> 5.3333333 | S31: =$A31/S$5 -> 64 | T31: =$A31/T$5 -> 21.333333 | V31: =$A31/V$5 -> 32 | W31: =$A31/W$5 -> 12.8 | Y31: =$A31/Y$5 -> 1.28 | Z31: =$A31/Z$5 -> 2.1333333 | AB31: =$A31/AB$5 -> 106.66667 | AC31: =$A31/AC$5 -> 8 | AE31: =$A31/AE$5 -> 320 | AF31: =$A31/AF$5 -> 32 | AH31: =$A31/AH$5 -> 320 | AI31: =$A31/AI$5 -> 320 | AK31: =$A31/AK$5 -> 320 | AL31: =$A31/AL$5 -> 320
A32: ='Soul Energy Tiers'!J8 -> 640 | C32: Tier VI | D32: =$A32/D$5 -> 4.6043165 | F32: Tier VI | G32: =$A32/G$5 -> 21.333333 | H32: =$A32/H$5 -> 10.666667 | J32: =$A32/J$5 -> 640 | K32: =$A32/K$5 -> 128 | M32: =$A32/M$5 -> 160 | N32: =$A32/N$5 -> 80 | P32: =$A32/P$5 -> 21.333333 | Q32: =$A32/Q$5 -> 10.666667 | S32: =$A32/S$5 -> 128 | T32: =$A32/T$5 -> 42.666667 | V32: =$A32/V$5 -> 64 | W32: =$A32/W$5 -> 25.6 | Y32: =$A32/Y$5 -> 2.56 | Z32: =$A32/Z$5 -> 4.2666667 | AB32: =$A32/AB$5 -> 213.33333 | AC32: =$A32/AC$5 -> 16 | AE32: =$A32/AE$5 -> 640 | AF32: =$A32/AF$5 -> 64 | AH32: =$A32/AH$5 -> 640 | AI32: =$A32/AI$5 -> 640 | AK32: =$A32/AK$5 -> 640 | AL32: =$A32/AL$5 -> 640
A33: ='Soul Energy Tiers'!J9 -> 1280 | C33: Tier VII | D33: =$A33/D$5 -> 9.2086331 | F33: Tier VII | G33: =$A33/G$5 -> 42.666667 | H33: =$A33/H$5 -> 21.333333 | J33: =$A33/J$5 -> 1280 | K33: =$A33/K$5 -> 256 | M33: =$A33/M$5 -> 320 | N33: =$A33/N$5 -> 160 | P33: =$A33/P$5 -> 42.666667 | Q33: =$A33/Q$5 -> 21.333333 | S33: =$A33/S$5 -> 256 | T33: =$A33/T$5 -> 85.333333 | V33: =$A33/V$5 -> 128 | W33: =$A33/W$5 -> 51.2 | Y33: =$A33/Y$5 -> 5.12 | Z33: =$A33/Z$5 -> 8.5333333 | AB33: =$A33/AB$5 -> 426.66667 | AC33: =$A33/AC$5 -> 32 | AE33: =$A33/AE$5 -> 1280 | AF33: =$A33/AF$5 -> 128 | AH33: =$A33/AH$5 -> 1280 | AI33: =$A33/AI$5 -> 1280 | AK33: =$A33/AK$5 -> 1280 | AL33: =$A33/AL$5 -> 1280
A34: ='Soul Energy Tiers'!J10 -> 2560 | C34: Tier VIII | D34: =$A34/D$5 -> 18.417266 | F34: Tier VIII | G34: =$A34/G$5 -> 85.333333 | H34: =$A34/H$5 -> 42.666667 | J34: =$A34/J$5 -> 2560 | K34: =$A34/K$5 -> 512 | M34: =$A34/M$5 -> 640 | N34: =$A34/N$5 -> 320 | P34: =$A34/P$5 -> 85.333333 | Q34: =$A34/Q$5 -> 42.666667 | S34: =$A34/S$5 -> 512 | T34: =$A34/T$5 -> 170.66667 | V34: =$A34/V$5 -> 256 | W34: =$A34/W$5 -> 102.4 | Y34: =$A34/Y$5 -> 10.24 | Z34: =$A34/Z$5 -> 17.066667 | AB34: =$A34/AB$5 -> 853.33333 | AC34: =$A34/AC$5 -> 64 | AE34: =$A34/AE$5 -> 2560 | AF34: =$A34/AF$5 -> 256 | AH34: =$A34/AH$5 -> 2560 | AI34: =$A34/AI$5 -> 2560 | AK34: =$A34/AK$5 -> 2560 | AL34: =$A34/AL$5 -> 2560
A35: ='Soul Energy Tiers'!J11 -> 5120 | C35: Tier IX | D35: =$A35/D$5 -> 36.834532 | F35: Tier IX | G35: =$A35/G$5 -> 170.66667 | H35: =$A35/H$5 -> 85.333333 | J35: =$A35/J$5 -> 5120 | K35: =$A35/K$5 -> 1024 | M35: =$A35/M$5 -> 1280 | N35: =$A35/N$5 -> 640 | P35: =$A35/P$5 -> 170.66667 | Q35: =$A35/Q$5 -> 85.333333 | S35: =$A35/S$5 -> 1024 | T35: =$A35/T$5 -> 341.33333 | V35: =$A35/V$5 -> 512 | W35: =$A35/W$5 -> 204.8 | Y35: =$A35/Y$5 -> 20.48 | Z35: =$A35/Z$5 -> 34.133333 | AB35: =$A35/AB$5 -> 1706.6667 | AC35: =$A35/AC$5 -> 128 | AE35: =$A35/AE$5 -> 5120 | AF35: =$A35/AF$5 -> 512 | AH35: =$A35/AH$5 -> 5120 | AI35: =$A35/AI$5 -> 5120 | AK35: =$A35/AK$5 -> 5120 | AL35: =$A35/AL$5 -> 5120
A36: ='Soul Energy Tiers'!J12 -> 10240 | C36: Tier X | D36: =$A36/D$5 -> 73.669065 | F36: Tier X | G36: =$A36/G$5 -> 341.33333 | H36: =$A36/H$5 -> 170.66667 | J36: =$A36/J$5 -> 10240 | K36: =$A36/K$5 -> 2048 | M36: =$A36/M$5 -> 2560 | N36: =$A36/N$5 -> 1280 | P36: =$A36/P$5 -> 341.33333 | Q36: =$A36/Q$5 -> 170.66667 | S36: =$A36/S$5 -> 2048 | T36: =$A36/T$5 -> 682.66667 | V36: =$A36/V$5 -> 1024 | W36: =$A36/W$5 -> 409.6 | Y36: =$A36/Y$5 -> 40.96 | Z36: =$A36/Z$5 -> 68.266667 | AB36: =$A36/AB$5 -> 3413.3333 | AC36: =$A36/AC$5 -> 256 | AE36: =$A36/AE$5 -> 10240 | AF36: =$A36/AF$5 -> 1024 | AH36: =$A36/AH$5 -> 10240 | AI36: =$A36/AI$5 -> 10240 | AK36: =$A36/AK$5 -> 10240 | AL36: =$A36/AL$5 -> 10240
A37: ='Soul Energy Tiers'!J13 -> 20480 | C37: Tier XI | D37: =$A37/D$5 -> 147.33813 | F37: Tier XI | G37: =$A37/G$5 -> 682.66667 | H37: =$A37/H$5 -> 341.33333 | J37: =$A37/J$5 -> 20480 | K37: =$A37/K$5 -> 4096 | M37: =$A37/M$5 -> 5120 | N37: =$A37/N$5 -> 2560 | P37: =$A37/P$5 -> 682.66667 | Q37: =$A37/Q$5 -> 341.33333 | S37: =$A37/S$5 -> 4096 | T37: =$A37/T$5 -> 1365.3333 | V37: =$A37/V$5 -> 2048 | W37: =$A37/W$5 -> 819.2 | Y37: =$A37/Y$5 -> 81.92 | Z37: =$A37/Z$5 -> 136.53333 | AB37: =$A37/AB$5 -> 6826.6667 | AC37: =$A37/AC$5 -> 512 | AE37: =$A37/AE$5 -> 20480 | AF37: =$A37/AF$5 -> 2048 | AH37: =$A37/AH$5 -> 20480 | AI37: =$A37/AI$5 -> 20480 | AK37: =$A37/AK$5 -> 20480 | AL37: =$A37/AL$5 -> 20480
A38: ='Soul Energy Tiers'!J14 -> 40960 | C38: Tier XII | D38: =$A38/D$5 -> 294.67626 | F38: Tier XII | G38: =$A38/G$5 -> 1365.3333 | H38: =$A38/H$5 -> 682.66667 | J38: =$A38/J$5 -> 40960 | K38: =$A38/K$5 -> 8192 | M38: =$A38/M$5 -> 10240 | N38: =$A38/N$5 -> 5120 | P38: =$A38/P$5 -> 1365.3333 | Q38: =$A38/Q$5 -> 682.66667 | S38: =$A38/S$5 -> 8192 | T38: =$A38/T$5 -> 2730.6667 | V38: =$A38/V$5 -> 4096 | W38: =$A38/W$5 -> 1638.4 | Y38: =$A38/Y$5 -> 163.84 | Z38: =$A38/Z$5 -> 273.06667 | AB38: =$A38/AB$5 -> 13653.333 | AC38: =$A38/AC$5 -> 1024 | AE38: =$A38/AE$5 -> 40960 | AF38: =$A38/AF$5 -> 4096 | AH38: =$A38/AH$5 -> 40960 | AI38: =$A38/AI$5 -> 40960 | AK38: =$A38/AK$5 -> 40960 | AL38: =$A38/AL$5 -> 40960
... A43: ='Soul Energy Tiers'!J19 -> 1310720 | C43: Tier XVII | D43: =$A43/D$5 -> 9429.6403 | F43: Tier XVII | G43: =$A43/G$5 -> 43690.667 | H43: =$A43/H$5 -> 21845.333 | J43: =$A43/J$5 -> 1310720 | K43: =$A43/K$5 -> 262144 | M43: =$A43/M$5 -> 327680 | N43: =$A43/N$5 -> 163840 | P43: =$A43/P$5 -> 43690.667 | Q43: =$A43/Q$5 -> 21845.333 | S43: =$A43/S$5 -> 262144 | T43: =$A43/T$5 -> 87381.333 | V43: =$A43/V$5 -> 131072 | W43: =$A43/W$5 -> 52428.8 | Y43: =$A43/Y$5 -> 5242.88 | Z43: =$A43/Z$5 -> 8738.1333 | AB43: =$A43/AB$5 -> 436906.67 | AC43: =$A43/AC$5 -> 32768 | AE43: =$A43/AE$5 -> 1310720 | AF43: =$A43/AF$5 -> 131072 | AH43: =$A43/AH$5 -> 1310720 | AI43: =$A43/AI$5 -> 1310720 | AK43: =$A43/AK$5 -> 1310720 | AL43: =$A43/AL$5 -> 1310720
G44: How Many YEARS does it take to recharge a spell
A45: Spell Soul Cost | C45: Soul Energy Tier | D45: Char | F45: Soul Energy Tier | G45: =G26 -> Finaies (Low) | H45: =H26 -> Finaies (High) | J45: =J26 -> Lishies (Low) | K45: =K26 -> Lishies (High) | M45: =M26 -> Buhraies (Low) | N45: =N26 -> Buhraies (High) | P45: =P26 -> Fuhraies (Low) | Q45: =Q26 -> Fuhraies (High) | S45: =S26 -> Darfaries (Low) | T45: =T26 -> Darfaries (High) | V45: =V26 -> Wozefaries (Low) | W45: =W26 -> Wozefaries (High) | Y45: =Y26 -> Sorefaries (Low) | Z45: =Z26 -> Sorefaries (High) | AB45: =AB26 -> Humans (Low) | AC45: =AC26 -> Humans (High) | AE45: =AE26 -> Cruros (Low) | AF45: =AF26 -> Cruros (High) | AH45: =AH26 | AI45: =AI26 | AK45: =AK26 | AL45: =AL26
A46: ='Soul Energy Tiers'!J3 -> 20 | C46: Tier I | D46: =($A46/D$5)/365 -> 0.00039420518 | F46: Tier I | G46: =($A46/G$5)/365 -> 0.001826484 | H46: =($A46/H$5)/365 -> 0.00091324201 | J46: =($A46/J$5)/365 -> 0.054794521 | K46: =($A46/K$5)/365 -> 0.010958904 | M46: =($A46/M$5)/365 -> 0.01369863 | N46: =($A46/N$5)/365 -> 0.0068493151 | P46: =($A46/P$5)/365 -> 0.001826484 | Q46: =($A46/Q$5)/365 -> 0.00091324201 | S46: =($A46/S$5)/365 -> 0.010958904 | T46: =($A46/T$5)/365 -> 0.003652968 | V46: =($A46/V$5)/365 -> 0.0054794521 | W46: =($A46/W$5)/365 -> 0.0021917808 | Y46: =($A46/Y$5)/365 -> 0.00021917808 | Z46: =($A46/Z$5)/365 -> 0.0003652968 | AB46: =($A46/AB$5)/365 -> 0.01826484 | AC46: =($A46/AC$5)/365 -> 0.001369863 | AE46: =($A46/AE$5)/365 -> 0.054794521 | AF46: =($A46/AF$5)/365 -> 0.0054794521 | AH46: =($A46/AH$5)/365 -> 0.054794521 | AI46: =($A46/AI$5)/365 -> 0.054794521 | AK46: =($A46/AK$5)/365 -> 0.054794521 | AL46: =($A46/AL$5)/365 -> 0.054794521
A47: ='Soul Energy Tiers'!J4 -> 40 | C47: Tier II | D47: =($A47/D$5)/365 -> 0.00078841037 | F47: Tier II | G47: =($A47/G$5)/365 -> 0.003652968 | H47: =($A47/H$5)/365 -> 0.001826484 | J47: =($A47/J$5)/365 -> 0.10958904 | K47: =($A47/K$5)/365 -> 0.021917808 | M47: =($A47/M$5)/365 -> 0.02739726 | N47: =($A47/N$5)/365 -> 0.01369863 | P47: =($A47/P$5)/365 -> 0.003652968 | Q47: =($A47/Q$5)/365 -> 0.001826484 | S47: =($A47/S$5)/365 -> 0.021917808 | T47: =($A47/T$5)/365 -> 0.0073059361 | V47: =($A47/V$5)/365 -> 0.010958904 | W47: =($A47/W$5)/365 -> 0.0043835616 | Y47: =($A47/Y$5)/365 -> 0.00043835616 | Z47: =($A47/Z$5)/365 -> 0.00073059361 | AB47: =($A47/AB$5)/365 -> 0.03652968 | AC47: =($A47/AC$5)/365 -> 0.002739726 | AE47: =($A47/AE$5)/365 -> 0.10958904 | AF47: =($A47/AF$5)/365 -> 0.010958904 | AH47: =($A47/AH$5)/365 -> 0.10958904 | AI47: =($A47/AI$5)/365 -> 0.10958904 | AK47: =($A47/AK$5)/365 -> 0.10958904 | AL47: =($A47/AL$5)/365 -> 0.10958904
A48: ='Soul Energy Tiers'!J5 -> 80 | C48: Tier III | D48: =($A48/D$5)/365 -> 0.0015768207 | F48: Tier III | G48: =($A48/G$5)/365 -> 0.0073059361 | H48: =($A48/H$5)/365 -> 0.003652968 | J48: =($A48/J$5)/365 -> 0.21917808 | K48: =($A48/K$5)/365 -> 0.043835616 | M48: =($A48/M$5)/365 -> 0.054794521 | N48: =($A48/N$5)/365 -> 0.02739726 | P48: =($A48/P$5)/365 -> 0.0073059361 | Q48: =($A48/Q$5)/365 -> 0.003652968 | S48: =($A48/S$5)/365 -> 0.043835616 | T48: =($A48/T$5)/365 -> 0.014611872 | V48: =($A48/V$5)/365 -> 0.021917808 | W48: =($A48/W$5)/365 -> 0.0087671233 | Y48: =($A48/Y$5)/365 -> 0.00087671233 | Z48: =($A48/Z$5)/365 -> 0.0014611872 | AB48: =($A48/AB$5)/365 -> 0.073059361 | AC48: =($A48/AC$5)/365 -> 0.0054794521 | AE48: =($A48/AE$5)/365 -> 0.21917808 | AF48: =($A48/AF$5)/365 -> 0.021917808 | AH48: =($A48/AH$5)/365 -> 0.21917808 | AI48: =($A48/AI$5)/365 -> 0.21917808 | AK48: =($A48/AK$5)/365 -> 0.21917808 | AL48: =($A48/AL$5)/365 -> 0.21917808
...

Sheet Fauna (Herbivores) Soul Avg + C
C1: CHAR CALC | G1: FAUNA (HERBIVORES) AVERAGE
A2: Below Child years is equals to shares of parents soul being infused | C2: Child | D2: =D3/12 -> 0.018939394 | F2: Child | G2: =G3/12 -> 0.037878788 | H2: =H3/12 -> 0.56818182 | I2: =I3/12 -> 0.18939394 | J2: =J3/12 -> 0.18939394 | K2: =K3/12 -> 0.9469697 | L2: =L3/12 -> 0.75757576 | M2: =M3/12 -> 0.41666667 | N2: =N3/12 -> 0.018939394 | ... AB2: =AB3/12 -> 0.018939394
C3: Adulthood | D3: =D4/4.4 -> 0.22727273 | F3: Adulthood | G3: =G4/4.4 -> 0.45454545 | H3: =H4/4.4 -> 6.8181818 | I3: =I4/4.4 -> 2.2727273 | J3: =J4/4.4 -> 2.2727273 | K3: =K4/4.4 -> 11.363636 | L3: =L4/4.4 -> 9.0909091 | M3: =M4/4.4 -> 5 | N3: =N4/4.4 -> 0.22727273 | ... AB3: =AB4/4.4 -> 0.22727273
C4: Lifespan | D4: 1 | F4: Lifespan | G4: 2 | H4: 30 | I4: 10 | J4: 10 | K4: 50 | L4: 40 | M4: 22 | N4: 1 | O4: 1 | P4: 1 | Q4: 1 | R4: 1 | S4: 1 | T4: 1 | U4: 1 | V4: 1 | W4: 1 | X4: 1 | Y4: 1 | Z4: 1 | AA4: 1 | AB4: 1
C5: Soul Recharge/Day | D5: 1 | F5: Soul Recharge/Day | G5: 2 | H5: 5 | I5: 2 | J5: 3 | K5: 4 | L5: 4 | M5: 6 | N5: 1 | O5: 1 | P5: 1 | Q5: 1 | R5: 1 | S5: 1 | T5: 1 | U5: 1 | V5: 1 | W5: 1 | X5: 1 | Y5: 1 | Z5: 1 | AA5: 1 | AB5: 1
G6: Average Total Years to Reach Tier
A7: Accumulative Total Cost | C7: Soul Energy Tier | D7: Char | F7: Soul Energy Tier | G7: Cinika | H7: Egua | I7: Legunia | J7: Koalin | K7: Monica | L7: Winga | M7: Wooly
A8: ='Soul Energy Tiers'!K3 -> 400 | C8: Tier I | D8: =($A8/D$5)/365 -> 1.0958904 | F8: Tier I | G8: =($A8/G$5)/365 -> 0.54794521 | H8: =($A8/H$5)/365 -> 0.21917808 | I8: =($A8/I$5)/365 -> 0.54794521 | J8: =($A8/J$5)/365 -> 0.3652968 | K8: =($A8/K$5)/365 -> 0.2739726 | L8: =($A8/L$5)/365 -> 0.2739726 | M8: =($A8/M$5)/365 -> 0.1826484 | N8: =($A8/N$5)/365 -> 1.0958904 | O8: =($A8/O$5)/365 -> 1.0958904 | P8: =($A8/N$5)/365 -> 1.0958904 | Q8: =($A8/O$5)/365 -> 1.0958904 | R8: =($A8/P$5)/365 -> 1.0958904 | S8: =($A8/Q$5)/365 -> 1.0958904 | T8: =($A8/R$5)/365 -> 1.0958904 | U8: =($A8/S$5)/365 -> 1.0958904 | V8: =($A8/T$5)/365 -> 1.0958904 | W8: =($A8/U$5)/365 -> 1.0958904 | ... AB8: =($A8/Z$5)/365 -> 1.0958904
A9: ='Soul Energy Tiers'!K4 -> 1200 | C9: Tier II | D9: =($A9/D$5)/365 -> 3.2876712 | F9: Tier II | G9: =($A9/G$5)/365 -> 1.6438356 | H9: =($A9/H$5)/365 -> 0.65753425 | I9: =($A9/I$5)/365 -> 1.6438356 | J9: =($A9/J$5)/365 -> 1.0958904 | K9: =($A9/K$5)/365 -> 0.82191781 | L9: =($A9/L$5)/365 -> 0.82191781 | M9: =($A9/M$5)/365 -> 0.54794521 | N9: =($A9/N$5)/365 -> 3.2876712 | O9: =($A9/O$5)/365 -> 3.2876712 | P9: =($A9/N$5)/365 -> 3.2876712 | Q9: =($A9/O$5)/365 -> 3.2876712 | R9: =($A9/P$5)/365 -> 3.2876712 | S9: =($A9/Q$5)/365 -> 3.2876712 | T9: =($A9/R$5)/365 -> 3.2876712 | U9: =($A9/S$5)/365 -> 3.2876712 | V9: =($A9/T$5)/365 -> 3.2876712 | W9: =($A9/U$5)/365 -> 3.2876712 | ... AB9: =($A9/Z$5)/365 -> 3.2876712
A10: ='Soul Energy Tiers'!K5 -> 2800 | C10: Tier III | D10: =($A10/D$5)/365 -> 7.6712329 | F10: Tier III | G10: =($A10/G$5)/365 -> 3.8356164 | H10: =($A10/H$5)/365 -> 1.5342466 | I10: =($A10/I$5)/365 -> 3.8356164 | J10: =($A10/J$5)/365 -> 2.5570776 | K10: =($A10/K$5)/365 -> 1.9178082 | L10: =($A10/L$5)/365 -> 1.9178082 | M10: =($A10/M$5)/365 -> 1.2785388 | N10: =($A10/N$5)/365 -> 7.6712329 | O10: =($A10/O$5)/365 -> 7.6712329 | P10: =($A10/N$5)/365 -> 7.6712329 | Q10: =($A10/O$5)/365 -> 7.6712329 | R10: =($A10/P$5)/365 -> 7.6712329 | S10: =($A10/Q$5)/365 -> 7.6712329 | T10: =($A10/R$5)/365 -> 7.6712329 | U10: =($A10/S$5)/365 -> 7.6712329 | V10: =($A10/T$5)/365 -> 7.6712329 | W10: =($A10/U$5)/365 -> 7.6712329 | ... AB10: =($A10/Z$5)/365 -> 7.6712329
A11: ='Soul Energy Tiers'!K6 -> 6000 | C11: Tier IV | D11: =($A11/D$5)/365 -> 16.438356 | F11: Tier IV | G11: =($A11/G$5)/365 -> 8.2191781 | H11: =($A11/H$5)/365 -> 3.2876712 | I11: =($A11/I$5)/365 -> 8.2191781 | J11: =($A11/J$5)/365 -> 5.4794521 | K11: =($A11/K$5)/365 -> 4.109589 | L11: =($A11/L$5)/365 -> 4.109589 | M11: =($A11/M$5)/365 -> 2.739726 | N11: =($A11/N$5)/365 -> 16.438356 | O11: =($A11/O$5)/365 -> 16.438356 | P11: =($A11/N$5)/365 -> 16.438356 | Q11: =($A11/O$5)/365 -> 16.438356 | R11: =($A11/P$5)/365 -> 16.438356 | S11: =($A11/Q$5)/365 -> 16.438356 | T11: =($A11/R$5)/365 -> 16.438356 | U11: =($A11/S$5)/365 -> 16.438356 | V11: =($A11/T$5)/365 -> 16.438356 | W11: =($A11/U$5)/365 -> 16.438356 | ... AB11: =($A11/Z$5)/365 -> 16.438356
A12: ='Soul Energy Tiers'!K7 -> 12400 | C12: Tier V | D12: =($A12/D$5)/365 -> 33.972603 | F12: Tier V | G12: =($A12/G$5)/365 -> 16.986301 | H12: =($A12/H$5)/365 -> 6.7945205 | I12: =($A12/I$5)/365 -> 16.986301 | J12: =($A12/J$5)/365 -> 11.324201 | K12: =($A12/K$5)/365 -> 8.4931507 | L12: =($A12/L$5)/365 -> 8.4931507 | M12: =($A12/M$5)/365 -> 5.6621005 | N12: =($A12/N$5)/365 -> 33.972603 | O12: =($A12/O$5)/365 -> 33.972603 | P12: =($A12/N$5)/365 -> 33.972603 | Q12: =($A12/O$5)/365 -> 33.972603 | R12: =($A12/P$5)/365 -> 33.972603 | S12: =($A12/Q$5)/365 -> 33.972603 | T12: =($A12/R$5)/365 -> 33.972603 | U12: =($A12/S$5)/365 -> 33.972603 | V12: =($A12/T$5)/365 -> 33.972603 | W12: =($A12/U$5)/365 -> 33.972603 | ... AB12: =($A12/Z$5)/365 -> 33.972603
A13: ='Soul Energy Tiers'!K8 -> 25200 | C13: Tier VI | D13: =($A13/D$5)/365 -> 69.041096 | F13: Tier VI | G13: =($A13/G$5)/365 -> 34.520548 | H13: =($A13/H$5)/365 -> 13.808219 | I13: =($A13/I$5)/365 -> 34.520548 | J13: =($A13/J$5)/365 -> 23.013699 | K13: =($A13/K$5)/365 -> 17.260274 | L13: =($A13/L$5)/365 -> 17.260274 | M13: =($A13/M$5)/365 -> 11.506849 | N13: =($A13/N$5)/365 -> 69.041096 | O13: =($A13/O$5)/365 -> 69.041096 | P13: =($A13/N$5)/365 -> 69.041096 | Q13: =($A13/O$5)/365 -> 69.041096 | R13: =($A13/P$5)/365 -> 69.041096 | S13: =($A13/Q$5)/365 -> 69.041096 | T13: =($A13/R$5)/365 -> 69.041096 | U13: =($A13/S$5)/365 -> 69.041096 | V13: =($A13/T$5)/365 -> 69.041096 | W13: =($A13/U$5)/365 -> 69.041096 | ... AB13: =($A13/Z$5)/365 -> 69.041096
A14: ='Soul Energy Tiers'!K9 -> 50800 | C14: Tier VII | D14: =($A14/D$5)/365 -> 139.17808 | F14: Tier VII | G14: =($A14/G$5)/365 -> 69.589041 | H14: =($A14/H$5)/365 -> 27.835616 | I14: =($A14/I$5)/365 -> 69.589041 | J14: =($A14/J$5)/365 -> 46.392694 | K14: =($A14/K$5)/365 -> 34.794521 | L14: =($A14/L$5)/365 -> 34.794521 | M14: =($A14/M$5)/365 -> 23.196347 | N14: =($A14/N$5)/365 -> 139.17808 | O14: =($A14/O$5)/365 -> 139.17808 | P14: =($A14/N$5)/365 -> 139.17808 | Q14: =($A14/O$5)/365 -> 139.17808 | R14: =($A14/P$5)/365 -> 139.17808 | S14: =($A14/Q$5)/365 -> 139.17808 | T14: =($A14/R$5)/365 -> 139.17808 | U14: =($A14/S$5)/365 -> 139.17808 | V14: =($A14/T$5)/365 -> 139.17808 | W14: =($A14/U$5)/365 -> 139.17808 | ... AB14: =($A14/Z$5)/365 -> 139.17808
A15: ='Soul Energy Tiers'!K10 -> 102000 | C15: Tier VIII | D15: =($A15/D$5)/365 -> 279.45205 | F15: Tier VIII | G15: =($A15/G$5)/365 -> 139.72603 | H15: =($A15/H$5)/365 -> 55.890411 | I15: =($A15/I$5)/365 -> 139.72603 | J15: =($A15/J$5)/365 -> 93.150685 | K15: =($A15/K$5)/365 -> 69.863014 | L15: =($A15/L$5)/365 -> 69.863014 | M15: =($A15/M$5)/365 -> 46.575342 | N15: =($A15/N$5)/365 -> 279.45205 | O15: =($A15/O$5)/365 -> 279.45205 | P15: =($A15/N$5)/365 -> 279.45205 | Q15: =($A15/O$5)/365 -> 279.45205 | R15: =($A15/P$5)/365 -> 279.45205 | S15: =($A15/Q$5)/365 -> 279.45205 | T15: =($A15/R$5)/365 -> 279.45205 | U15: =($A15/S$5)/365 -> 279.45205 | V15: =($A15/T$5)/365 -> 279.45205 | W15: =($A15/U$5)/365 -> 279.45205 | ... AB15: =($A15/Z$5)/365 -> 279.45205
A16: ='Soul Energy Tiers'!K11 -> 204400 | C16: Tier IX | D16: =($A16/D$5)/365 -> 560 | F16: Tier IX | G16: =($A16/G$5)/365 -> 280 | H16: =($A16/H$5)/365 -> 112 | I16: =($A16/I$5)/365 -> 280 | J16: =($A16/J$5)/365 -> 186.66667 | K16: =($A16/K$5)/365 -> 140 | L16: =($A16/L$5)/365 -> 140 | M16: =($A16/M$5)/365 -> 93.333333 | N16: =($A16/N$5)/365 -> 560 | O16: =($A16/O$5)/365 -> 560 | P16: =($A16/N$5)/365 -> 560 | Q16: =($A16/O$5)/365 -> 560 | R16: =($A16/P$5)/365 -> 560 | S16: =($A16/Q$5)/365 -> 560 | T16: =($A16/R$5)/365 -> 560 | U16: =($A16/S$5)/365 -> 560 | V16: =($A16/T$5)/365 -> 560 | W16: =($A16/U$5)/365 -> 560 | ... AB16: =($A16/Z$5)/365 -> 560
A17: ='Soul Energy Tiers'!K12 -> 409200 | C17: Tier X | D17: =($A17/D$5)/365 -> 1121.0959 | F17: Tier X | G17: =($A17/G$5)/365 -> 560.54795 | H17: =($A17/H$5)/365 -> 224.21918 | I17: =($A17/I$5)/365 -> 560.54795 | J17: =($A17/J$5)/365 -> 373.69863 | K17: =($A17/K$5)/365 -> 280.27397 | L17: =($A17/L$5)/365 -> 280.27397 | M17: =($A17/M$5)/365 -> 186.84932 | N17: =($A17/N$5)/365 -> 1121.0959 | O17: =($A17/O$5)/365 -> 1121.0959 | P17: =($A17/N$5)/365 -> 1121.0959 | Q17: =($A17/O$5)/365 -> 1121.0959 | R17: =($A17/P$5)/365 -> 1121.0959 | S17: =($A17/Q$5)/365 -> 1121.0959 | T17: =($A17/R$5)/365 -> 1121.0959 | U17: =($A17/S$5)/365 -> 1121.0959 | V17: =($A17/T$5)/365 -> 1121.0959 | W17: =($A17/U$5)/365 -> 1121.0959 | ... AB17: =($A17/Z$5)/365 -> 1121.0959
A18: ='Soul Energy Tiers'!K13 -> 818800 | C18: Tier XI | D18: =($A18/D$5)/365 -> 2243.2877 | F18: Tier XI | G18: =($A18/G$5)/365 -> 1121.6438 | H18: =($A18/H$5)/365 -> 448.65753 | I18: =($A18/I$5)/365 -> 1121.6438 | J18: =($A18/J$5)/365 -> 747.76256 | K18: =($A18/K$5)/365 -> 560.82192 | L18: =($A18/L$5)/365 -> 560.82192 | M18: =($A18/M$5)/365 -> 373.88128 | N18: =($A18/N$5)/365 -> 2243.2877 | O18: =($A18/O$5)/365 -> 2243.2877 | P18: =($A18/N$5)/365 -> 2243.2877 | Q18: =($A18/O$5)/365 -> 2243.2877 | R18: =($A18/P$5)/365 -> 2243.2877 | S18: =($A18/Q$5)/365 -> 2243.2877 | T18: =($A18/R$5)/365 -> 2243.2877 | U18: =($A18/S$5)/365 -> 2243.2877 | V18: =($A18/T$5)/365 -> 2243.2877 | W18: =($A18/U$5)/365 -> 2243.2877 | ... AB18: =($A18/Z$5)/365 -> 2243.2877
A19: ='Soul Energy Tiers'!K14 -> 1638000 | C19: Tier XII | D19: =($A19/D$5)/365 -> 4487.6712 | F19: Tier XII | G19: =($A19/G$5)/365 -> 2243.8356 | H19: =($A19/H$5)/365 -> 897.53425 | I19: =($A19/I$5)/365 -> 2243.8356 | J19: =($A19/J$5)/365 -> 1495.8904 | K19: =($A19/K$5)/365 -> 1121.9178 | L19: =($A19/L$5)/365 -> 1121.9178 | M19: =($A19/M$5)/365 -> 747.94521 | N19: =($A19/N$5)/365 -> 4487.6712 | O19: =($A19/O$5)/365 -> 4487.6712 | P19: =($A19/N$5)/365 -> 4487.6712 | Q19: =($A19/O$5)/365 -> 4487.6712 | R19: =($A19/P$5)/365 -> 4487.6712 | S19: =($A19/Q$5)/365 -> 4487.6712 | T19: =($A19/R$5)/365 -> 4487.6712 | U19: =($A19/S$5)/365 -> 4487.6712 | V19: =($A19/T$5)/365 -> 4487.6712 | W19: =($A19/U$5)/365 -> 4487.6712 | ... AB19: =($A19/Z$5)/365 -> 4487.6712
... A24: ='Soul Energy Tiers'!K19 -> 52428400 | C24: Tier XVII | D24: =($A24/D$5)/365 -> 143639.45 | F24: Tier XVII | G24: =($A24/G$5)/365 -> 71819.726 | H24: =($A24/H$5)/365 -> 28727.89 | I24: =($A24/I$5)/365 -> 71819.726 | J24: =($A24/J$5)/365 -> 47879.817 | K24: =($A24/K$5)/365 -> 35909.863 | L24: =($A24/L$5)/365 -> 35909.863 | M24: =($A24/M$5)/365 -> 23939.909 | N24: =($A24/N$5)/365 -> 143639.45 | O24: =($A24/O$5)/365 -> 143639.45 | P24: =($A24/N$5)/365 -> 143639.45 | Q24: =($A24/O$5)/365 -> 143639.45 | R24: =($A24/P$5)/365 -> 143639.45 | S24: =($A24/Q$5)/365 -> 143639.45 | T24: =($A24/R$5)/365 -> 143639.45 | U24: =($A24/S$5)/365 -> 143639.45 | V24: =($A24/T$5)/365 -> 143639.45 | W24: =($A24/U$5)/365 -> 143639.45 | ... AB24: =($A24/Z$5)/365 -> 143639.45
G25: How Many days does it take to recharge a spell
A26: Spell Soul Cost | C26: Soul Energy Tier | D26: Char | F26: Soul Energy Tier | G26: =G7 -> Cinika | H26: =H7 -> Egua | I26: =I7 -> Legunia | J26: =J7 -> Koalin | K26: =K7 -> Monica | L26: =L7 -> Winga | M26: =M7 -> Wooly | N26: =N7 | ... AB26: =AB7
A27: ='Soul Energy Tiers'!J3 -> 20 | C27: Tier I | D27: =$A27/D$5 -> 20 | F27: Tier I | G27: =$A27/G$5 -> 10 | H27: =$A27/H$5 -> 4 | I27: =$A27/I$5 -> 10 | J27: =$A27/J$5 -> 6.6666667 | K27: =$A27/K$5 -> 5 | L27: =$A27/L$5 -> 5 | M27: =$A27/M$5 -> 3.3333333 | N27: =$A27/N$5 -> 20 | ... AB27: =$A27/AB$5 -> 20
A28: ='Soul Energy Tiers'!J4 -> 40 | C28: Tier II | D28: =$A28/D$5 -> 40 | F28: Tier II | G28: =$A28/G$5 -> 20 | H28: =$A28/H$5 -> 8 | I28: =$A28/I$5 -> 20 | J28: =$A28/J$5 -> 13.333333 | K28: =$A28/K$5 -> 10 | L28: =$A28/L$5 -> 10 | M28: =$A28/M$5 -> 6.6666667 | N28: =$A28/N$5 -> 40 | ... AB28: =$A28/AB$5 -> 40
A29: ='Soul Energy Tiers'!J5 -> 80 | C29: Tier III | D29: =$A29/D$5 -> 80 | F29: Tier III | G29: =$A29/G$5 -> 40 | H29: =$A29/H$5 -> 16 | I29: =$A29/I$5 -> 40 | J29: =$A29/J$5 -> 26.666667 | K29: =$A29/K$5 -> 20 | L29: =$A29/L$5 -> 20 | M29: =$A29/M$5 -> 13.333333 | N29: =$A29/N$5 -> 80 | ... AB29: =$A29/AB$5 -> 80
A30: ='Soul Energy Tiers'!J6 -> 160 | C30: Tier IV | D30: =$A30/D$5 -> 160 | F30: Tier IV | G30: =$A30/G$5 -> 80 | H30: =$A30/H$5 -> 32 | I30: =$A30/I$5 -> 80 | J30: =$A30/J$5 -> 53.333333 | K30: =$A30/K$5 -> 40 | L30: =$A30/L$5 -> 40 | M30: =$A30/M$5 -> 26.666667 | N30: =$A30/N$5 -> 160 | ... AB30: =$A30/AB$5 -> 160
A31: ='Soul Energy Tiers'!J7 -> 320 | C31: Tier V | D31: =$A31/D$5 -> 320 | F31: Tier V | G31: =$A31/G$5 -> 160 | H31: =$A31/H$5 -> 64 | I31: =$A31/I$5 -> 160 | J31: =$A31/J$5 -> 106.66667 | K31: =$A31/K$5 -> 80 | L31: =$A31/L$5 -> 80 | M31: =$A31/M$5 -> 53.333333 | N31: =$A31/N$5 -> 320 | ... AB31: =$A31/AB$5 -> 320
A32: ='Soul Energy Tiers'!J8 -> 640 | C32: Tier VI | D32: =$A32/D$5 -> 640 | F32: Tier VI | G32: =$A32/G$5 -> 320 | H32: =$A32/H$5 -> 128 | I32: =$A32/I$5 -> 320 | J32: =$A32/J$5 -> 213.33333 | K32: =$A32/K$5 -> 160 | L32: =$A32/L$5 -> 160 | M32: =$A32/M$5 -> 106.66667 | N32: =$A32/N$5 -> 640 | ... AB32: =$A32/AB$5 -> 640
A33: ='Soul Energy Tiers'!J9 -> 1280 | C33: Tier VII | D33: =$A33/D$5 -> 1280 | F33: Tier VII | G33: =$A33/G$5 -> 640 | H33: =$A33/H$5 -> 256 | I33: =$A33/I$5 -> 640 | J33: =$A33/J$5 -> 426.66667 | K33: =$A33/K$5 -> 320 | L33: =$A33/L$5 -> 320 | M33: =$A33/M$5 -> 213.33333 | N33: =$A33/N$5 -> 1280 | ... AB33: =$A33/AB$5 -> 1280
A34: ='Soul Energy Tiers'!J10 -> 2560 | C34: Tier VIII | D34: =$A34/D$5 -> 2560 | F34: Tier VIII | G34: =$A34/G$5 -> 1280 | H34: =$A34/H$5 -> 512 | I34: =$A34/I$5 -> 1280 | J34: =$A34/J$5 -> 853.33333 | K34: =$A34/K$5 -> 640 | L34: =$A34/L$5 -> 640 | M34: =$A34/M$5 -> 426.66667 | N34: =$A34/N$5 -> 2560 | ... AB34: =$A34/AB$5 -> 2560
A35: ='Soul Energy Tiers'!J11 -> 5120 | C35: Tier IX | D35: =$A35/D$5 -> 5120 | F35: Tier IX | G35: =$A35/G$5 -> 2560 | H35: =$A35/H$5 -> 1024 | I35: =$A35/I$5 -> 2560 | J35: =$A35/J$5 -> 1706.6667 | K35: =$A35/K$5 -> 1280 | L35: =$A35/L$5 -> 1280 | M35: =$A35/M$5 -> 853.33333 | N35: =$A35/N$5 -> 5120 | ... AB35: =$A35/AB$5 -> 5120
A36: ='Soul Energy Tiers'!J12 -> 10240 | C36: Tier X | D36: =$A36/D$5 -> 10240 | F36: Tier X | G36: =$A36/G$5 -> 5120 | H36: =$A36/H$5 -> 2048 | I36: =$A36/I$5 -> 5120 | J36: =$A36/J$5 -> 3413.3333 | K36: =$A36/K$5 -> 2560 | L36: =$A36/L$5 -> 2560 | M36: =$A36/M$5 -> 1706.6667 | N36: =$A36/N$5 -> 10240 | ... AB36: =$A36/AB$5 -> 10240
A37: ='Soul Energy Tiers'!J13 -> 20480 | C37: Tier XI | D37: =$A37/D$5 -> 20480 | F37: Tier XI | G37: =$A37/G$5 -> 10240 | H37: =$A37/H$5 -> 4096 | I37: =$A37/I$5 -> 10240 | J37: =$A37/J$5 -> 6826.6667 | K37: =$A37/K$5 -> 5120 | L37: =$A37/L$5 -> 5120 | M37: =$A37/M$5 -> 3413.3333 | N37: =$A37/N$5 -> 20480 | ... AB37: =$A37/AB$5 -> 20480
A38: ='Soul Energy Tiers'!J14 -> 40960 | C38: Tier XII | D38: =$A38/D$5 -> 40960 | F38: Tier XII | G38: =$A38/G$5 -> 20480 | H38: =$A38/H$5 -> 8192 | I38: =$A38/I$5 -> 20480 | J38: =$A38/J$5 -> 13653.333 | K38: =$A38/K$5 -> 10240 | L38: =$A38/L$5 -> 10240 | M38: =$A38/M$5 -> 6826.6667 | N38: =$A38/N$5 -> 40960 | ... AB38: =$A38/AB$5 -> 40960
... A43: ='Soul Energy Tiers'!J19 -> 1310720 | C43: Tier XVII | D43: =$A43/D$5 -> 1310720 | F43: Tier XVII | G43: =$A43/G$5 -> 655360 | H43: =$A43/H$5 -> 262144 | I43: =$A43/I$5 -> 655360 | J43: =$A43/J$5 -> 436906.67 | K43: =$A43/K$5 -> 327680 | L43: =$A43/L$5 -> 327680 | M43: =$A43/M$5 -> 218453.33 | N43: =$A43/N$5 -> 1310720 | ... AB43: =$A43/AB$5 -> 1310720
G44: How Many YEARS does it take to recharge a spell
A45: Spell Soul Cost | C45: Soul Energy Tier | D45: Char | F45: Soul Energy Tier | G45: =G26 -> Cinika | H45: =H26 -> Egua | I45: =I26 -> Legunia | J45: =J26 -> Koalin | K45: =K26 -> Monica | L45: =L26 -> Winga | M45: =M26 -> Wooly | N45: =N26 | ... AB45: =AB26
A46: ='Soul Energy Tiers'!J3 -> 20 | C46: Tier I | D46: =($A46/D$5)/365 -> 0.054794521 | F46: Tier I | G46: =($A46/G$5)/365 -> 0.02739726 | H46: =($A46/H$5)/365 -> 0.010958904 | I46: =($A46/I$5)/365 -> 0.02739726 | J46: =($A46/J$5)/365 -> 0.01826484 | K46: =($A46/K$5)/365 -> 0.01369863 | L46: =($A46/L$5)/365 -> 0.01369863 | M46: =($A46/M$5)/365 -> 0.0091324201 | N46: =($A46/N$5)/365 -> 0.054794521 | ... AB46: =($A46/AB$5)/365 -> 0.054794521
A47: ='Soul Energy Tiers'!J4 -> 40 | C47: Tier II | D47: =($A47/D$5)/365 -> 0.10958904 | F47: Tier II | G47: =($A47/G$5)/365 -> 0.054794521 | H47: =($A47/H$5)/365 -> 0.021917808 | I47: =($A47/I$5)/365 -> 0.054794521 | J47: =($A47/J$5)/365 -> 0.03652968 | K47: =($A47/K$5)/365 -> 0.02739726 | L47: =($A47/L$5)/365 -> 0.02739726 | M47: =($A47/M$5)/365 -> 0.01826484 | N47: =($A47/N$5)/365 -> 0.10958904 | ... AB47: =($A47/AB$5)/365 -> 0.10958904
A48: ='Soul Energy Tiers'!J5 -> 80 | C48: Tier III | D48: =($A48/D$5)/365 -> 0.21917808 | F48: Tier III | G48: =($A48/G$5)/365 -> 0.10958904 | H48: =($A48/H$5)/365 -> 0.043835616 | I48: =($A48/I$5)/365 -> 0.10958904 | J48: =($A48/J$5)/365 -> 0.073059361 | K48: =($A48/K$5)/365 -> 0.054794521 | L48: =($A48/L$5)/365 -> 0.054794521 | M48: =($A48/M$5)/365 -> 0.03652968 | N48: =($A48/N$5)/365 -> 0.21917808 | ... AB48: =($A48/AB$5)/365 -> 0.21917808
...

Sheet Fauna (Carnivores) Soul Avg + C
C1: CHAR CALC | G1: FAUNA (HERBIVORES) AVERAGE
A2: Below Child years is equals to shares of parents soul being infused | C2: Child | D2: =D3/12 -> 0.018939394 | F2: Child | G2: =G3/12 -> 0.18939394 | H2: =H3/12 -> 0.75757576 | I2: =I3/12 -> 0.47348485 | J2: =J3/12 -> 0.11363636 | K2: =K3/12 -> 0.28409091 | L2: =L3/12 -> 0.22727273 | M2: =M3/12 -> 0.28409091 | N2: =N3/12 -> 0.018939394 | ... AB2: =AB3/12 -> 0.018939394
C3: Adulthood | D3: =D4/4.4 -> 0.22727273 | F3: Adulthood | G3: =G4/4.4 -> 2.2727273 | H3: =H4/4.4 -> 9.0909091 | I3: =I4/4.4 -> 5.6818182 | J3: =J4/4.4 -> 1.3636364 | K3: =K4/4.4 -> 3.4090909 | L3: =L4/4.4 -> 2.7272727 | M3: =M4/4.4 -> 3.4090909 | N3: =N4/4.4 -> 0.22727273 | ... AB3: =AB4/4.4 -> 0.22727273
C4: Lifespan | D4: 1 | F4: Lifespan | G4: 10 | H4: 40 | I4: 25 | J4: 6 | K4: 15 | L4: 12 | M4: 15 | N4: 1 | O4: 1 | P4: 1 | Q4: 1 | R4: 1 | S4: 1 | T4: 1 | U4: 1 | V4: 1 | W4: 1 | X4: 1 | Y4: 1 | Z4: 1 | AA4: 1 | AB4: 1
C5: Soul Recharge/Day | D5: 1 | F5: Soul Recharge/Day | G5: 2 | H5: 3 | I5: 4 | J5: 1 | K5: 2 | L5: 2 | M5: 10 | N5: 1 | O5: 1 | P5: 1 | Q5: 1 | R5: 1 | S5: 1 | T5: 1 | U5: 1 | V5: 1 | W5: 1 | X5: 1 | Y5: 1 | Z5: 1 | AA5: 1 | AB5: 1
G6: Average Total Years to Reach Tier
A7: Accumulative Total Cost | C7: Soul Energy Tier | D7: Char | F7: Soul Energy Tier | G7: Barina | H7: Crocus | I7: Fatupari | J7: Fihi | K7: Sanbi | L7: Sayna | M7: Wozen
A8: ='Soul Energy Tiers'!K3 -> 400 | C8: Tier I | D8: =($A8/D$5)/365 -> 1.0958904 | F8: Tier I | G8: =($A8/G$5)/365 -> 0.54794521 | H8: =($A8/H$5)/365 -> 0.3652968 | I8: =($A8/I$5)/365 -> 0.2739726 | J8: =($A8/J$5)/365 -> 1.0958904 | K8: =($A8/K$5)/365 -> 0.54794521 | L8: =($A8/L$5)/365 -> 0.54794521 | M8: =($A8/M$5)/365 -> 0.10958904 | N8: =($A8/N$5)/365 -> 1.0958904 | O8: =($A8/O$5)/365 -> 1.0958904 | P8: =($A8/N$5)/365 -> 1.0958904 | Q8: =($A8/O$5)/365 -> 1.0958904 | R8: =($A8/P$5)/365 -> 1.0958904 | S8: =($A8/Q$5)/365 -> 1.0958904 | T8: =($A8/R$5)/365 -> 1.0958904 | U8: =($A8/S$5)/365 -> 1.0958904 | V8: =($A8/T$5)/365 -> 1.0958904 | W8: =($A8/U$5)/365 -> 1.0958904 | ... AB8: =($A8/Z$5)/365 -> 1.0958904
A9: ='Soul Energy Tiers'!K4 -> 1200 | C9: Tier II | D9: =($A9/D$5)/365 -> 3.2876712 | F9: Tier II | G9: =($A9/G$5)/365 -> 1.6438356 | H9: =($A9/H$5)/365 -> 1.0958904 | I9: =($A9/I$5)/365 -> 0.82191781 | J9: =($A9/J$5)/365 -> 3.2876712 | K9: =($A9/K$5)/365 -> 1.6438356 | L9: =($A9/L$5)/365 -> 1.6438356 | M9: =($A9/M$5)/365 -> 0.32876712 | N9: =($A9/N$5)/365 -> 3.2876712 | O9: =($A9/O$5)/365 -> 3.2876712 | P9: =($A9/N$5)/365 -> 3.2876712 | Q9: =($A9/O$5)/365 -> 3.2876712 | R9: =($A9/P$5)/365 -> 3.2876712 | S9: =($A9/Q$5)/365 -> 3.2876712 | T9: =($A9/R$5)/365 -> 3.2876712 | U9: =($A9/S$5)/365 -> 3.2876712 | V9: =($A9/T$5)/365 -> 3.2876712 | W9: =($A9/U$5)/365 -> 3.2876712 | ... AB9: =($A9/Z$5)/365 -> 3.2876712
A10: ='Soul Energy Tiers'!K5 -> 2800 | C10: Tier III | D10: =($A10/D$5)/365 -> 7.6712329 | F10: Tier III | G10: =($A10/G$5)/365 -> 3.8356164 | H10: =($A10/H$5)/365 -> 2.5570776 | I10: =($A10/I$5)/365 -> 1.9178082 | J10: =($A10/J$5)/365 -> 7.6712329 | K10: =($A10/K$5)/365 -> 3.8356164 | L10: =($A10/L$5)/365 -> 3.8356164 | M10: =($A10/M$5)/365 -> 0.76712329 | N10: =($A10/N$5)/365 -> 7.6712329 | O10: =($A10/O$5)/365 -> 7.6712329 | P10: =($A10/N$5)/365 -> 7.6712329 | Q10: =($A10/O$5)/365 -> 7.6712329 | R10: =($A10/P$5)/365 -> 7.6712329 | S10: =($A10/Q$5)/365 -> 7.6712329 | T10: =($A10/R$5)/365 -> 7.6712329 | U10: =($A10/S$5)/365 -> 7.6712329 | V10: =($A10/T$5)/365 -> 7.6712329 | W10: =($A10/U$5)/365 -> 7.6712329 | ... AB10: =($A10/Z$5)/365 -> 7.6712329
A11: ='Soul Energy Tiers'!K6 -> 6000 | C11: Tier IV | D11: =($A11/D$5)/365 -> 16.438356 | F11: Tier IV | G11: =($A11/G$5)/365 -> 8.2191781 | H11: =($A11/H$5)/365 -> 5.4794521 | I11: =($A11/I$5)/365 -> 4.109589 | J11: =($A11/J$5)/365 -> 16.438356 | K11: =($A11/K$5)/365 -> 8.2191781 | L11: =($A11/L$5)/365 -> 8.2191781 | M11: =($A11/M$5)/365 -> 1.6438356 | N11: =($A11/N$5)/365 -> 16.438356 | O11: =($A11/O$5)/365 -> 16.438356 | P11: =($A11/N$5)/365 -> 16.438356 | Q11: =($A11/O$5)/365 -> 16.438356 | R11: =($A11/P$5)/365 -> 16.438356 | S11: =($A11/Q$5)/365 -> 16.438356 | T11: =($A11/R$5)/365 -> 16.438356 | U11: =($A11/S$5)/365 -> 16.438356 | V11: =($A11/T$5)/365 -> 16.438356 | W11: =($A11/U$5)/365 -> 16.438356 | ... AB11: =($A11/Z$5)/365 -> 16.438356
A12: ='Soul Energy Tiers'!K7 -> 12400 | C12: Tier V | D12: =($A12/D$5)/365 -> 33.972603 | F12: Tier V | G12: =($A12/G$5)/365 -> 16.986301 | H12: =($A12/H$5)/365 -> 11.324201 | I12: =($A12/I$5)/365 -> 8.4931507 | J12: =($A12/J$5)/365 -> 33.972603 | K12: =($A12/K$5)/365 -> 16.986301 | L12: =($A12/L$5)/365 -> 16.986301 | M12: =($A12/M$5)/365 -> 3.3972603 | N12: =($A12/N$5)/365 -> 33.972603 | O12: =($A12/O$5)/365 -> 33.972603 | P12: =($A12/N$5)/365 -> 33.972603 | Q12: =($A12/O$5)/365 -> 33.972603 | R12: =($A12/P$5)/365 -> 33.972603 | S12: =($A12/Q$5)/365 -> 33.972603 | T12: =($A12/R$5)/365 -> 33.972603 | U12: =($A12/S$5)/365 -> 33.972603 | V12: =($A12/T$5)/365 -> 33.972603 | W12: =($A12/U$5)/365 -> 33.972603 | ... AB12: =($A12/Z$5)/365 -> 33.972603
